Workbook

Sheet Index
B1: Index
A2: 1 | B2: Income Statement
A3: 2 | B3: Balance Sheet
A4: 3 | B4: Comparative Income Statement
A5: 4 | B5: Comparative Balance Sheet
A6: 5 | B6: Common Size Income Statement
A7: 6 | B7: Common Size Balance Sheet

Sheet IS
A1: Income Statement of Tata Motors from FY2020 TO FY2024
A2: Particulars | B2: FY2024 | C2: FY2023 | D2: FY2022 | E2: FY2021 | F2: FY2020
A3: I. Revenue from operations
A4: (a) Revenue | B4: 72745.92 | C4: 65298.84 | D4: 46880.97 | E4: 46559.39 | F4: 43485.76
A5: (b) Other operating revenue | B5: 557.16 | C5: 458.49 | D5: 382.71 | E5: 472.08 | F5: 442.41
A6: Total revenue from operations (I) | B6: 73303.08 | C6: 65757.33 | D6: 47263.68 | E6: 47031.47 | F6: 43928.17
A7: II. Other Income | B7: 1149.88 | C7: 820.94 | D7: 659.91 | E7: 842.96 | F7: 1383.05
A8: III. Total Income (I+II) | B8: 74452.96 | C8: 66578.27 | D8: 47923.59 | E8: 47874.43 | F8: 45311.22
A9: IV. Expenses:
A10: (a) Cost of materials consumed | B10: 46757.28 | C10: 42226.81 | D10: 31693.11 | E10: 28493.12 | F10: 26171.85
A11: (b) Purchases of products for sale | B11: 6707.03 | C11: 6561.32 | D11: 5030 | E11: 7518.05 | F11: 5679.98
A12: (c) Changes in Stock | B12: 1736.35 | C12: 484.69 | D12: -403.87 | E12: -108.48 | F12: 722.68
A13: (d) Employee benefits expense | B13: 4308.15 | C13: 4021.63 | D13: 3601.51 | E13: 3987.72 | F13: 4384.31
A14: (e) Finance costs | B14: 1705.74 | C14: 2047.51 | D14: 2121.73 | E14: 2288.61 | F14: 1973
A15: (f) Foreign exchange loss (net) | B15: 200.72 | C15: 279.76 | D15: 136.81 | E15: 29.02 | F15: 239
A16: (g) Depreciation and amortisation expense | B16: 2016.84 | C16: 1766.86 | D16: 1760.57 | E16: 3325.8 | F16: 3375.29
A17: (h) Product development/Engineering expenses | B17: 1104.79 | C17: 899.06 | D17: 593.9 | E17: 907.44 | F17: 830.24
A18: (i) Other expenses | B18: 7610.15 | C18: 7819.74 | D18: 6018.71 | E18: 5612.48 | F18: 7720.75
A19: (j) Amount transferred to capital and other accounts | B19: -1129.73 | C19: -1066.73 | D19: -905.42 | E19: -817.53 | F19: -1169.46
A20: Total Expenses (IV) | B20: 69317.32 | C20: 65040.65 | D20: 49647.05 | E20: 51239.38 | F20: 49927.64
A21: V. Profit/(Loss) before exceptional items and tax (III-IV) | B21: 5135.64 | C21: 1537.62 | D21: -1723.46 | E21: -3364.95 | F21: -4616.42
... A27: XI. Total comprehensive income/(loss) for the year | B27: 8338.64 | C27: 2451.64 | D27: -1267.18 | E27: -1952.45 | F27: -7668.35

Sheet BS
A1: Balance Sheet of Tata Motors from FY2020 TO FY2024
A2: Particulars | B2: FY2024 | C2: FY2023 | D2: FY2022 | E2: FY2021 | F2: FY2020
A3: I. ASSETS
A4: (1) NON-CURRENT ASSETS | B4: 36133.09 | C4: 33060.22 | D4: 30958.82 | E4: 30283.65 | F4: 47242.06
A5: Property, plant and equipment (PPE) | B5: 12056.24 | C5: 12176.6 | D5: 11811.02 | E5: 17143.04 | F5: 18870.67
A6: Capital work-in-progress (CWIP) | B6: 575.65 | C6: 575.65 | D6: 585.21 | E6: 1324.21 | F6: 1755.51
A7: Right of use assets (ROU) | B7: 338.25 | C7: 344.2 | D7: 332.45 | E7: 979.48 | F7: 669.58
A8: Goodwill | B8: 99.09 | C8: 99.09 | D8: 99.09 | E8: 99.09 | F8: 99.09
A9: Other intangible assets | B9: 1768.49 | C9: 1914.76 | D9: 2009.87 | E9: 6156.56 | F9: 5568.64
A10: Intangible assets under development | B10: 509.3 | C10: 509.3 | D10: 882.03 | E10: 1604.23 | F10: 2739.29
A11: Investments in subsidiaries, JVs & associates | B11: 25819.34 | C11: 27976.8 | D11: 24723.34 | E11: 14287.8 | F11: 15182.29
A12: Financial assets (Investments, Loans, Others) | B12: -1283.47 | C12: -1402.16 | D12: -1507.57 | E12: 1691.01 | F12: 2204.53
A13: Non-current tax assets (Net) | B13: 1751.48 | C13: 1909.8 | D13: 1847.16 | E13: 741.02 | F13: 727.97
A14: Other non-current assets | B14: -1301.98 | C14: -1439.42 | D14: -2059.45 | E14: 1056.77 | F14: 1208.08
A15: (2) CURRENT ASSETS | B15: 36258.71 | C15: 26868.97 | D15: 26792.13 | E15: 25309.78 | F15: 7861.82
... A20: TOTAL ASSETS (1) + (2) | B20: 72391.8 | C20: 59929.19 | D20: 57750.95 | E20: 55593.43 | F20: 55103.88
A22: II. EQUITY AND LIABILITIES
A23: (1) EQUITY | B23: 34068.79 | C23: 28683.65 | D23: 27786.17 | E23: 27173.34 | F23: 24545.91
A24: Equity share capital | B24: 766.49 | C24: 766.02 | D24: 765.88 | E24: 765.81 | F24: 719.54
A25: Other equity | B25: 33302.3 | C25: 27917.63 | D25: 27020.29 | E25: 26407.53 | F25: 23826.37
A26: (2) NON-CURRENT LIABILITIES | B26: 14449.18 | C26: 10501.71 | D26: 9436.56 | E26: 10544.75 | F26: 13293.48
A27: Financial liabilities (Borrowings & Lease) | B27: 11632.4 | C27: 7654.51 | D27: 6560.85 | E27: 7728.84 | F27: 10234.34
A28: Provisions | B28: 2752.48 | C28: 2787.05 | D28: 2828.53 | E28: 2776.99 | F28: 3030.14
A29: Deferred tax liabilities (Net) | B29: -7.8 | C29: 1.83 | D29: 1.84 | E29: -373.19 | F29: 7.92
A30: Other non-current liabilities | B30: 72.1 | C30: 58.32 | D30: 45.34 | E30: 412 | F30: 21.08
A31: (3) CURRENT LIABILITIES | B31: 23873.83 | C31: 20743.83 | D31: 20528.22 | E31: 17875.34 | F31: 17264.49
A32: Financial liabilities (Borrowings, Trade Payables, Others) | B32: 22234.33 | C32: 18973.91 | D32: 18913.34 | E32: 16339.06 | F32: 15360.7
A33: Provisions | B33: 1023.7 | C33: 1087.49 | D33: 913.04 | E33: 910.16 | F33: 1043.54
A34: Current tax liabilities (Net) | B34: 148.16 | C34: 212.72 | D34: 19.82 | E34: 87.05 | F34: 295.34
... A36: TOTAL EQUITY AND LIABILITIES (1) + (2) + (3) | B36: 72391.8 | C36: 59929.19 | D36: 57750.95 | E36: 55593.43 | F36: 55103.88

Sheet IS_XLOOPUP
A1: =IS!A1 -> Income Statement of Tata Motors from FY2020 TO FY2024
A2: =IS!A2 -> Particulars | B2: =IS!B2 -> FY2024 | C2: =IS!C2 -> FY2023 | D2: =IS!D2 -> FY2022 | E2: =IS!E2 -> FY2021 | F2: =IS!F2 -> FY2020
A3: =IS!A3 -> I. Revenue from operations
A4: =IS!A4 -> (a) Revenue | B4: =_xlfn.XLOOKUP($A4,IS!$A$1:$A$27,IS!B$1:B$27," ",0,1) -> 72745.92 | C4: =_xlfn.XLOOKUP($A4,IS!$A$1:$A$27,IS!C$1:C$27," ",0,1) -> 65298.84 | D4: =_xlfn.XLOOKUP($A4,IS!$A$1:$A$27,IS!D$1:D$27," ",0,1) -> 46880.97 | E4: =_xlfn.XLOOKUP($A4,IS!$A$1:$A$27,IS!E$1:E$27," ",0,1) -> 46559.39 | F4: =_xlfn.XLOOKUP($A4,IS!$A$1:$A$27,IS!F$1:F$27," ",0,1) -> 43485.76
A5: =IS!A5 -> (b) Other operating revenue | B5: =_xlfn.XLOOKUP($A5,IS!$A$1:$A$27,IS!B$1:B$27," ",0,1) -> 557.16 | C5: =_xlfn.XLOOKUP($A5,IS!$A$1:$A$27,IS!C$1:C$27," ",0,1) -> 458.49 | D5: =_xlfn.XLOOKUP($A5,IS!$A$1:$A$27,IS!D$1:D$27," ",0,1) -> 382.71 | E5: =_xlfn.XLOOKUP($A5,IS!$A$1:$A$27,IS!E$1:E$27," ",0,1) -> 472.08 | F5: =_xlfn.XLOOKUP($A5,IS!$A$1:$A$27,IS!F$1:F$27," ",0,1) -> 442.41
A6: =IS!A6 -> Total revenue from operations (I) | B6: =_xlfn.XLOOKUP($A6,IS!$A$1:$A$27,IS!B$1:B$27," ",0,1) -> 73303.08 | C6: =_xlfn.XLOOKUP($A6,IS!$A$1:$A$27,IS!C$1:C$27," ",0,1) -> 65757.33 | D6: =_xlfn.XLOOKUP($A6,IS!$A$1:$A$27,IS!D$1:D$27," ",0,1) -> 47263.68 | E6: =_xlfn.XLOOKUP($A6,IS!$A$1:$A$27,IS!E$1:E$27," ",0,1) -> 47031.47 | F6: =_xlfn.XLOOKUP($A6,IS!$A$1:$A$27,IS!F$1:F$27," ",0,1) -> 43928.17
A7: =IS!A7 -> II. Other Income | B7: =_xlfn.XLOOKUP($A7,IS!$A$1:$A$27,IS!B$1:B$27," ",0,1) -> 1149.88 | C7: =_xlfn.XLOOKUP($A7,IS!$A$1:$A$27,IS!C$1:C$27," ",0,1) -> 820.94 | D7: =_xlfn.XLOOKUP($A7,IS!$A$1:$A$27,IS!D$1:D$27," ",0,1) -> 659.91 | E7: =_xlfn.XLOOKUP($A7,IS!$A$1:$A$27,IS!E$1:E$27," ",0,1) -> 842.96 | F7: =_xlfn.XLOOKUP($A7,IS!$A$1:$A$27,IS!F$1:F$27," ",0,1) -> 1383.05
A8: =IS!A8 -> III. Total Income (I+II) | B8: =_xlfn.XLOOKUP($A8,IS!$A$1:$A$27,IS!B$1:B$27," ",0,1) -> 74452.96 | C8: =_xlfn.XLOOKUP($A8,IS!$A$1:$A$27,IS!C$1:C$27," ",0,1) -> 66578.27 | D8: =_xlfn.XLOOKUP($A8,IS!$A$1:$A$27,IS!D$1:D$27," ",0,1) -> 47923.59 | E8: =_xlfn.XLOOKUP($A8,IS!$A$1:$A$27,IS!E$1:E$27," ",0,1) -> 47874.43 | F8: =_xlfn.XLOOKUP($A8,IS!$A$1:$A$27,IS!F$1:F$27," ",0,1) -> 45311.22
A9: =IS!A9 -> IV. Expenses: | B9: =_xlfn.XLOOKUP($A9,IS!$A$1:$A$27,IS!B$1:B$27," ",0,1) -> 0 | C9: =_xlfn.XLOOKUP($A9,IS!$A$1:$A$27,IS!C$1:C$27," ",0,1) -> 0 | D9: =_xlfn.XLOOKUP($A9,IS!$A$1:$A$27,IS!D$1:D$27," ",0,1) -> 0 | E9: =_xlfn.XLOOKUP($A9,IS!$A$1:$A$27,IS!E$1:E$27," ",0,1) -> 0 | F9: =_xlfn.XLOOKUP($A9,IS!$A$1:$A$27,IS!F$1:F$27," ",0,1) -> 0
A10: =IS!A10 -> (a) Cost of materials consumed | B10: =_xlfn.XLOOKUP($A10,IS!$A$1:$A$27,IS!B$1:B$27," ",0,1) -> 46757.28 | C10: =_xlfn.XLOOKUP($A10,IS!$A$1:$A$27,IS!C$1:C$27," ",0,1) -> 42226.81 | D10: =_xlfn.XLOOKUP($A10,IS!$A$1:$A$27,IS!D$1:D$27," ",0,1) -> 31693.11 | E10: =_xlfn.XLOOKUP($A10,IS!$A$1:$A$27,IS!E$1:E$27," ",0,1) -> 28493.12 | F10: =_xlfn.XLOOKUP($A10,IS!$A$1:$A$27,IS!F$1:F$27," ",0,1) -> 26171.85
A11: =IS!A11 -> (b) Purchases of products for sale | B11: =_xlfn.XLOOKUP($A11,IS!$A$1:$A$27,IS!B$1:B$27," ",0,1) -> 6707.03 | C11: =_xlfn.XLOOKUP($A11,IS!$A$1:$A$27,IS!C$1:C$27," ",0,1) -> 6561.32 | D11: =_xlfn.XLOOKUP($A11,IS!$A$1:$A$27,IS!D$1:D$27," ",0,1) -> 5030 | E11: =_xlfn.XLOOKUP($A11,IS!$A$1:$A$27,IS!E$1:E$27," ",0,1) -> 7518.05 | F11: =_xlfn.XLOOKUP($A11,IS!$A$1:$A$27,IS!F$1:F$27," ",0,1) -> 5679.98
A12: =IS!A12 -> (c) Changes in Stock | B12: =_xlfn.XLOOKUP($A12,IS!$A$1:$A$27,IS!B$1:B$27," ",0,1) -> 1736.35 | C12: =_xlfn.XLOOKUP($A12,IS!$A$1:$A$27,IS!C$1:C$27," ",0,1) -> 484.69 | D12: =_xlfn.XLOOKUP($A12,IS!$A$1:$A$27,IS!D$1:D$27," ",0,1) -> -403.87 | E12: =_xlfn.XLOOKUP($A12,IS!$A$1:$A$27,IS!E$1:E$27," ",0,1) -> -108.48 | F12: =_xlfn.XLOOKUP($A12,IS!$A$1:$A$27,IS!F$1:F$27," ",0,1) -> 722.68
A13: =IS!A13 -> (d) Employee benefits expense | B13: =_xlfn.XLOOKUP($A13,IS!$A$1:$A$27,IS!B$1:B$27," ",0,1) -> 4308.15 | C13: =_xlfn.XLOOKUP($A13,IS!$A$1:$A$27,IS!C$1:C$27," ",0,1) -> 4021.63 | D13: =_xlfn.XLOOKUP($A13,IS!$A$1:$A$27,IS!D$1:D$27," ",0,1) -> 3601.51 | E13: =_xlfn.XLOOKUP($A13,IS!$A$1:$A$27,IS!E$1:E$27," ",0,1) -> 3987.72 | F13: =_xlfn.XLOOKUP($A13,IS!$A$1:$A$27,IS!F$1:F$27," ",0,1) -> 4384.31
A14: =IS!A14 -> (e) Finance costs | B14: =_xlfn.XLOOKUP($A14,IS!$A$1:$A$27,IS!B$1:B$27," ",0,1) -> 1705.74 | C14: =_xlfn.XLOOKUP($A14,IS!$A$1:$A$27,IS!C$1:C$27," ",0,1) -> 2047.51 | D14: =_xlfn.XLOOKUP($A14,IS!$A$1:$A$27,IS!D$1:D$27," ",0,1) -> 2121.73 | E14: =_xlfn.XLOOKUP($A14,IS!$A$1:$A$27,IS!E$1:E$27," ",0,1) -> 2288.61 | F14: =_xlfn.XLOOKUP($A14,IS!$A$1:$A$27,IS!F$1:F$27," ",0,1) -> 1973
A15: =IS!A15 -> (f) Foreign exchange loss (net) | B15: =_xlfn.XLOOKUP($A15,IS!$A$1:$A$27,IS!B$1:B$27," ",0,1) -> 200.72 | C15: =_xlfn.XLOOKUP($A15,IS!$A$1:$A$27,IS!C$1:C$27," ",0,1) -> 279.76 | D15: =_xlfn.XLOOKUP($A15,IS!$A$1:$A$27,IS!D$1:D$27," ",0,1) -> 136.81 | E15: =_xlfn.XLOOKUP($A15,IS!$A$1:$A$27,IS!E$1:E$27," ",0,1) -> 29.02 | F15: =_xlfn.XLOOKUP($A15,IS!$A$1:$A$27,IS!F$1:F$27," ",0,1) -> 239
... A27: =IS!A27 -> XI. Total comprehensive income/(loss) for the year | B27: =_xlfn.XLOOKUP($A27,IS!$A$1:$A$27,IS!B$1:B$27," ",0,1) -> 8338.64 | C27: =_xlfn.XLOOKUP($A27,IS!$A$1:$A$27,IS!C$1:C$27," ",0,1) -> 2451.64 | D27: =_xlfn.XLOOKUP($A27,IS!$A$1:$A$27,IS!D$1:D$27," ",0,1) -> -1267.18 | E27: =_xlfn.XLOOKUP($A27,IS!$A$1:$A$27,IS!E$1:E$27," ",0,1) -> -1952.45 | F27: =_xlfn.XLOOKUP($A27,IS!$A$1:$A$27,IS!F$1:F$27," ",0,1) -> -7668.35

Sheet IS_VLOOKUP
A1: =IS!A1 -> Income Statement of Tata Motors from FY2020 TO FY2024
A2: 1 | B2: 2 | C2: 3 | D2: 4 | E2: 5 | F2: 6
A3: =IS!A2 -> Particulars | B3: =IS!B2 -> FY2024 | C3: =IS!C2 -> FY2023 | D3: =IS!D2 -> FY2022 | E3: =IS!E2 -> FY2021 | F3: =IS!F2 -> FY2020
A4: =IS!A3 -> I. Revenue from operations
A5: =IS!A4 -> (a) Revenue | B5: =IFERROR(VLOOKUP($A5,IS!$A$1:$F$27,B$2,FALSE),"") -> 72745.92 | C5: =IFERROR(VLOOKUP($A5,IS!$A$1:$F$27,C$2,FALSE),"") -> 65298.84 | D5: =IFERROR(VLOOKUP($A5,IS!$A$1:$F$27,D$2,FALSE),"") -> 46880.97 | E5: =IFERROR(VLOOKUP($A5,IS!$A$1:$F$27,E$2,FALSE),"") -> 46559.39 | F5: =IFERROR(VLOOKUP($A5,IS!$A$1:$F$27,F$2,FALSE),"") -> 43485.76
A6: =IS!A5 -> (b) Other operating revenue | B6: =IFERROR(VLOOKUP($A6,IS!$A$1:$F$27,B$2,FALSE),"") -> 557.16 | C6: =IFERROR(VLOOKUP($A6,IS!$A$1:$F$27,C$2,FALSE),"") -> 458.49 | D6: =IFERROR(VLOOKUP($A6,IS!$A$1:$F$27,D$2,FALSE),"") -> 382.71 | E6: =IFERROR(VLOOKUP($A6,IS!$A$1:$F$27,E$2,FALSE),"") -> 472.08 | F6: =IFERROR(VLOOKUP($A6,IS!$A$1:$F$27,F$2,FALSE),"") -> 442.41
A7: =IS!A6 -> Total revenue from operations (I) | B7: =IFERROR(VLOOKUP($A7,IS!$A$1:$F$27,B$2,FALSE),"") -> 73303.08 | C7: =IFERROR(VLOOKUP($A7,IS!$A$1:$F$27,C$2,FALSE),"") -> 65757.33 | D7: =IFERROR(VLOOKUP($A7,IS!$A$1:$F$27,D$2,FALSE),"") -> 47263.68 | E7: =IFERROR(VLOOKUP($A7,IS!$A$1:$F$27,E$2,FALSE),"") -> 47031.47 | F7: =IFERROR(VLOOKUP($A7,IS!$A$1:$F$27,F$2,FALSE),"") -> 43928.17
A8: =IS!A7 -> II. Other Income | B8: =IFERROR(VLOOKUP($A8,IS!$A$1:$F$27,B$2,FALSE),"") -> 1149.88 | C8: =IFERROR(VLOOKUP($A8,IS!$A$1:$F$27,C$2,FALSE),"") -> 820.94 | D8: =IFERROR(VLOOKUP($A8,IS!$A$1:$F$27,D$2,FALSE),"") -> 659.91 | E8: =IFERROR(VLOOKUP($A8,IS!$A$1:$F$27,E$2,FALSE),"") -> 842.96 | F8: =IFERROR(VLOOKUP($A8,IS!$A$1:$F$27,F$2,FALSE),"") -> 1383.05
A9: =IS!A8 -> III. Total Income (I+II) | B9: =IFERROR(VLOOKUP($A9,IS!$A$1:$F$27,B$2,FALSE),"") -> 74452.96 | C9: =IFERROR(VLOOKUP($A9,IS!$A$1:$F$27,C$2,FALSE),"") -> 66578.27 | D9: =IFERROR(VLOOKUP($A9,IS!$A$1:$F$27,D$2,FALSE),"") -> 47923.59 | E9: =IFERROR(VLOOKUP($A9,IS!$A$1:$F$27,E$2,FALSE),"") -> 47874.43 | F9: =IFERROR(VLOOKUP($A9,IS!$A$1:$F$27,F$2,FALSE),"") -> 45311.22
A10: =IS!A9 -> IV. Expenses:
A11: =IS!A10 -> (a) Cost of materials consumed | B11: =IFERROR(VLOOKUP($A11,IS!$A$1:$F$27,B$2,FALSE),"") -> 46757.28 | C11: =IFERROR(VLOOKUP($A11,IS!$A$1:$F$27,C$2,FALSE),"") -> 42226.81 | D11: =IFERROR(VLOOKUP($A11,IS!$A$1:$F$27,D$2,FALSE),"") -> 31693.11 | E11: =IFERROR(VLOOKUP($A11,IS!$A$1:$F$27,E$2,FALSE),"") -> 28493.12 | F11: =IFERROR(VLOOKUP($A11,IS!$A$1:$F$27,F$2,FALSE),"") -> 26171.85
A12: =IS!A11 -> (b) Purchases of products for sale | B12: =IFERROR(VLOOKUP($A12,IS!$A$1:$F$27,B$2,FALSE),"") -> 6707.03 | C12: =IFERROR(VLOOKUP($A12,IS!$A$1:$F$27,C$2,FALSE),"") -> 6561.32 | D12: =IFERROR(VLOOKUP($A12,IS!$A$1:$F$27,D$2,FALSE),"") -> 5030 | E12: =IFERROR(VLOOKUP($A12,IS!$A$1:$F$27,E$2,FALSE),"") -> 7518.05 | F12: =IFERROR(VLOOKUP($A12,IS!$A$1:$F$27,F$2,FALSE),"") -> 5679.98
A13: =IS!A12 -> (c) Changes in Stock | B13: =IFERROR(VLOOKUP($A13,IS!$A$1:$F$27,B$2,FALSE),"") -> 1736.35 | C13: =IFERROR(VLOOKUP($A13,IS!$A$1:$F$27,C$2,FALSE),"") -> 484.69 | D13: =IFERROR(VLOOKUP($A13,IS!$A$1:$F$27,D$2,FALSE),"") -> -403.87 | E13: =IFERROR(VLOOKUP($A13,IS!$A$1:$F$27,E$2,FALSE),"") -> -108.48 | F13: =IFERROR(VLOOKUP($A13,IS!$A$1:$F$27,F$2,FALSE),"") -> 722.68
A14: =IS!A13 -> (d) Employee benefits expense | B14: =IFERROR(VLOOKUP($A14,IS!$A$1:$F$27,B$2,FALSE),"") -> 4308.15 | C14: =IFERROR(VLOOKUP($A14,IS!$A$1:$F$27,C$2,FALSE),"") -> 4021.63 | D14: =IFERROR(VLOOKUP($A14,IS!$A$1:$F$27,D$2,FALSE),"") -> 3601.51 | E14: =IFERROR(VLOOKUP($A14,IS!$A$1:$F$27,E$2,FALSE),"") -> 3987.72 | F14: =IFERROR(VLOOKUP($A14,IS!$A$1:$F$27,F$2,FALSE),"") -> 4384.31
A15: =IS!A14 -> (e) Finance costs | B15: =IFERROR(VLOOKUP($A15,IS!$A$1:$F$27,B$2,FALSE),"") -> 1705.74 | C15: =IFERROR(VLOOKUP($A15,IS!$A$1:$F$27,C$2,FALSE),"") -> 2047.51 | D15: =IFERROR(VLOOKUP($A15,IS!$A$1:$F$27,D$2,FALSE),"") -> 2121.73 | E15: =IFERROR(VLOOKUP($A15,IS!$A$1:$F$27,E$2,FALSE),"") -> 2288.61 | F15: =IFERROR(VLOOKUP($A15,IS!$A$1:$F$27,F$2,FALSE),"") -> 1973
A16: =IS!A15 -> (f) Foreign exchange loss (net) | B16: =IFERROR(VLOOKUP($A16,IS!$A$1:$F$27,B$2,FALSE),"") -> 200.72 | C16: =IFERROR(VLOOKUP($A16,IS!$A$1:$F$27,C$2,FALSE),"") -> 279.76 | D16: =IFERROR(VLOOKUP($A16,IS!$A$1:$F$27,D$2,FALSE),"") -> 136.81 | E16: =IFERROR(VLOOKUP($A16,IS!$A$1:$F$27,E$2,FALSE),"") -> 29.02 | F16: =IFERROR(VLOOKUP($A16,IS!$A$1:$F$27,F$2,FALSE),"") -> 239
A17: =IS!A16 -> (g) Depreciation and amortisation expense | B17: =IFERROR(VLOOKUP($A17,IS!$A$1:$F$27,B$2,FALSE),"") -> 2016.84 | C17: =IFERROR(VLOOKUP($A17,IS!$A$1:$F$27,C$2,FALSE),"") -> 1766.86 | D17: =IFERROR(VLOOKUP($A17,IS!$A$1:$F$27,D$2,FALSE),"") -> 1760.57 | E17: =IFERROR(VLOOKUP($A17,IS!$A$1:$F$27,E$2,FALSE),"") -> 3325.8 | F17: =IFERROR(VLOOKUP($A17,IS!$A$1:$F$27,F$2,FALSE),"") -> 3375.29
A18: =IS!A17 -> (h) Product development/Engineering expenses | B18: =IFERROR(VLOOKUP($A18,IS!$A$1:$F$27,B$2,FALSE),"") -> 1104.79 | C18: =IFERROR(VLOOKUP($A18,IS!$A$1:$F$27,C$2,FALSE),"") -> 899.06 | D18: =IFERROR(VLOOKUP($A18,IS!$A$1:$F$27,D$2,FALSE),"") -> 593.9 | E18: =IFERROR(VLOOKUP($A18,IS!$A$1:$F$27,E$2,FALSE),"") -> 907.44 | F18: =IFERROR(VLOOKUP($A18,IS!$A$1:$F$27,F$2,FALSE),"") -> 830.24
A19: =IS!A18 -> (i) Other expenses | B19: =IFERROR(VLOOKUP($A19,IS!$A$1:$F$27,B$2,FALSE),"") -> 7610.15 | C19: =IFERROR(VLOOKUP($A19,IS!$A$1:$F$27,C$2,FALSE),"") -> 7819.74 | D19: =IFERROR(VLOOKUP($A19,IS!$A$1:$F$27,D$2,FALSE),"") -> 6018.71 | E19: =IFERROR(VLOOKUP($A19,IS!$A$1:$F$27,E$2,FALSE),"") -> 5612.48 | F19: =IFERROR(VLOOKUP($A19,IS!$A$1:$F$27,F$2,FALSE),"") -> 7720.75
A20: =IS!A19 -> (j) Amount transferred to capital and other accounts | B20: =IFERROR(VLOOKUP($A20,IS!$A$1:$F$27,B$2,FALSE),"") -> -1129.73 | C20: =IFERROR(VLOOKUP($A20,IS!$A$1:$F$27,C$2,FALSE),"") -> -1066.73 | D20: =IFERROR(VLOOKUP($A20,IS!$A$1:$F$27,D$2,FALSE),"") -> -905.42 | E20: =IFERROR(VLOOKUP($A20,IS!$A$1:$F$27,E$2,FALSE),"") -> -817.53 | F20: =IFERROR(VLOOKUP($A20,IS!$A$1:$F$27,F$2,FALSE),"") -> -1169.46
A21: =IS!A20 -> Total Expenses (IV) | B21: =IFERROR(VLOOKUP($A21,IS!$A$1:$F$27,B$2,FALSE),"") -> 69317.32 | C21: =IFERROR(VLOOKUP($A21,IS!$A$1:$F$27,C$2,FALSE),"") -> 65040.65 | D21: =IFERROR(VLOOKUP($A21,IS!$A$1:$F$27,D$2,FALSE),"") -> 49647.05 | E21: =IFERROR(VLOOKUP($A21,IS!$A$1:$F$27,E$2,FALSE),"") -> 51239.38 | F21: =IFERROR(VLOOKUP($A21,IS!$A$1:$F$27,F$2,FALSE),"") -> 49927.64
A22: =IS!A21 -> V. Profit/(Loss) before exceptional items and tax (III-IV) | B22: =IFERROR(VLOOKUP($A22,IS!$A$1:$F$27,B$2,FALSE),"") -> 5135.64 | C22: =IFERROR(VLOOKUP($A22,IS!$A$1:$F$27,C$2,FALSE),"") -> 1537.62 | D22: =IFERROR(VLOOKUP($A22,IS!$A$1:$F$27,D$2,FALSE),"") -> -1723.46 | E22: =IFERROR(VLOOKUP($A22,IS!$A$1:$F$27,E$2,FALSE),"") -> -3364.95 | F22: =IFERROR(VLOOKUP($A22,IS!$A$1:$F$27,F$2,FALSE),"") -> -4616.42
... A28: =IS!A27 -> XI. Total comprehensive income/(loss) for the year | B28: =IFERROR(VLOOKUP($A28,IS!$A$1:$F$27,B$2,FALSE),"") -> 8338.64 | C28: =IFERROR(VLOOKUP($A28,IS!$A$1:$F$27,C$2,FALSE),"") -> 2451.64 | D28: =IFERROR(VLOOKUP($A28,IS!$A$1:$F$27,D$2,FALSE),"") -> -1267.18 | E28: =IFERROR(VLOOKUP($A28,IS!$A$1:$F$27,E$2,FALSE),"") -> -1952.45 | F28: =IFERROR(VLOOKUP($A28,IS!$A$1:$F$27,F$2,FALSE),"") -> -7668.35

Sheet IS_COMP
A1: =IS!A1 -> Income Statement of Tata Motors from FY2020 TO FY2024 | B1: comparative Income Statement
A2: =IS!A2 -> Particulars | B2: =IS!B2 -> FY2024 | C2: =IS!C2 -> FY2023 | D2: =IS!D2 -> FY2022 | E2: =IS!E2 -> FY2021 | F2: Trend
A3: =IS!A3 -> I. Revenue from operations
A4: =IS!A4 -> (a) Revenue | B4: =IFERROR((_xlfn.XLOOKUP($A4,IS!$A$1:$A$27,IS!B$1:B$27," ",0,1)/_xlfn.XLOOKUP($A4,IS!$A$1:$A$27,IS!C$1:C$27," ",0,1)) -1,"") -> 0.11404613 | C4: =IFERROR((_xlfn.XLOOKUP($A4,IS!$A$1:$A$27,IS!C$1:C$27," ",0,1)/_xlfn.XLOOKUP($A4,IS!$A$1:$A$27,IS!D$1:D$27," ",0,1)) -1,"") -> 0.39286452 | D4: =IFERROR((_xlfn.XLOOKUP($A4,IS!$A$1:$A$27,IS!D$1:D$27," ",0,1)/_xlfn.XLOOKUP($A4,IS!$A$1:$A$27,IS!E$1:E$27," ",0,1)) -1,"") -> 0.0069068774 | E4: =IFERROR((_xlfn.XLOOKUP($A4,IS!$A$1:$A$27,IS!E$1:E$27," ",0,1)/_xlfn.XLOOKUP($A4,IS!$A$1:$A$27,IS!F$1:F$27," ",0,1)) -1,"") -> 0.070681299
A5: =IS!A5 -> (b) Other operating revenue | B5: =IFERROR((_xlfn.XLOOKUP($A5,IS!$A$1:$A$27,IS!B$1:B$27," ",0,1)/_xlfn.XLOOKUP($A5,IS!$A$1:$A$27,IS!C$1:C$27," ",0,1)) -1,"") -> 0.21520644 | C5: =IFERROR((_xlfn.XLOOKUP($A5,IS!$A$1:$A$27,IS!C$1:C$27," ",0,1)/_xlfn.XLOOKUP($A5,IS!$A$1:$A$27,IS!D$1:D$27," ",0,1)) -1,"") -> 0.19800894 | D5: =IFERROR((_xlfn.XLOOKUP($A5,IS!$A$1:$A$27,IS!D$1:D$27," ",0,1)/_xlfn.XLOOKUP($A5,IS!$A$1:$A$27,IS!E$1:E$27," ",0,1)) -1,"") -> -0.18931113 | E5: =IFERROR((_xlfn.XLOOKUP($A5,IS!$A$1:$A$27,IS!E$1:E$27," ",0,1)/_xlfn.XLOOKUP($A5,IS!$A$1:$A$27,IS!F$1:F$27," ",0,1)) -1,"") -> 0.067064488
A6: =IS!A6 -> Total revenue from operations (I) | B6: =IFERROR((_xlfn.XLOOKUP($A6,IS!$A$1:$A$27,IS!B$1:B$27," ",0,1)/_xlfn.XLOOKUP($A6,IS!$A$1:$A$27,IS!C$1:C$27," ",0,1)) -1,"") -> 0.11475147 | C6: =IFERROR((_xlfn.XLOOKUP($A6,IS!$A$1:$A$27,IS!C$1:C$27," ",0,1)/_xlfn.XLOOKUP($A6,IS!$A$1:$A$27,IS!D$1:D$27," ",0,1)) -1,"") -> 0.39128671 | D6: =IFERROR((_xlfn.XLOOKUP($A6,IS!$A$1:$A$27,IS!D$1:D$27," ",0,1)/_xlfn.XLOOKUP($A6,IS!$A$1:$A$27,IS!E$1:E$27," ",0,1)) -1,"") -> 0.0049373324 | E6: =IFERROR((_xlfn.XLOOKUP($A6,IS!$A$1:$A$27,IS!E$1:E$27," ",0,1)/_xlfn.XLOOKUP($A6,IS!$A$1:$A$27,IS!F$1:F$27," ",0,1)) -1,"") -> 0.070644873
A7: =IS!A7 -> II. Other Income | B7: =IFERROR((_xlfn.XLOOKUP($A7,IS!$A$1:$A$27,IS!B$1:B$27," ",0,1)/_xlfn.XLOOKUP($A7,IS!$A$1:$A$27,IS!C$1:C$27," ",0,1)) -1,"") -> 0.40068702 | C7: =IFERROR((_xlfn.XLOOKUP($A7,IS!$A$1:$A$27,IS!C$1:C$27," ",0,1)/_xlfn.XLOOKUP($A7,IS!$A$1:$A$27,IS!D$1:D$27," ",0,1)) -1,"") -> 0.24401812 | D7: =IFERROR((_xlfn.XLOOKUP($A7,IS!$A$1:$A$27,IS!D$1:D$27," ",0,1)/_xlfn.XLOOKUP($A7,IS!$A$1:$A$27,IS!E$1:E$27," ",0,1)) -1,"") -> -0.21715147 | E7: =IFERROR((_xlfn.XLOOKUP($A7,IS!$A$1:$A$27,IS!E$1:E$27," ",0,1)/_xlfn.XLOOKUP($A7,IS!$A$1:$A$27,IS!F$1:F$27," ",0,1)) -1,"") -> -0.39050649
A8: =IS!A8 -> III. Total Income (I+II) | B8: =IFERROR((_xlfn.XLOOKUP($A8,IS!$A$1:$A$27,IS!B$1:B$27," ",0,1)/_xlfn.XLOOKUP($A8,IS!$A$1:$A$27,IS!C$1:C$27," ",0,1)) -1,"") -> 0.11827718 | C8: =IFERROR((_xlfn.XLOOKUP($A8,IS!$A$1:$A$27,IS!C$1:C$27," ",0,1)/_xlfn.XLOOKUP($A8,IS!$A$1:$A$27,IS!D$1:D$27," ",0,1)) -1,"") -> 0.38925882 | D8: =IFERROR((_xlfn.XLOOKUP($A8,IS!$A$1:$A$27,IS!D$1:D$27," ",0,1)/_xlfn.XLOOKUP($A8,IS!$A$1:$A$27,IS!E$1:E$27," ",0,1)) -1,"") -> 0.001026853 | E8: =IFERROR((_xlfn.XLOOKUP($A8,IS!$A$1:$A$27,IS!E$1:E$27," ",0,1)/_xlfn.XLOOKUP($A8,IS!$A$1:$A$27,IS!F$1:F$27," ",0,1)) -1,"") -> 0.056568991
A9: =IS!A9 -> IV. Expenses: | B9: =IFERROR((_xlfn.XLOOKUP($A9,IS!$A$1:$A$27,IS!B$1:B$27," ",0,1)/_xlfn.XLOOKUP($A9,IS!$A$1:$A$27,IS!C$1:C$27," ",0,1)) -1,"") | C9: =IFERROR((_xlfn.XLOOKUP($A9,IS!$A$1:$A$27,IS!C$1:C$27," ",0,1)/_xlfn.XLOOKUP($A9,IS!$A$1:$A$27,IS!D$1:D$27," ",0,1)) -1,"") | D9: =IFERROR((_xlfn.XLOOKUP($A9,IS!$A$1:$A$27,IS!D$1:D$27," ",0,1)/_xlfn.XLOOKUP($A9,IS!$A$1:$A$27,IS!E$1:E$27," ",0,1)) -1,"") | E9: =IFERROR((_xlfn.XLOOKUP($A9,IS!$A$1:$A$27,IS!E$1:E$27," ",0,1)/_xlfn.XLOOKUP($A9,IS!$A$1:$A$27,IS!F$1:F$27," ",0,1)) -1,"")
A10: =IS!A10 -> (a) Cost of materials consumed | B10: =IFERROR((_xlfn.XLOOKUP($A10,IS!$A$1:$A$27,IS!B$1:B$27," ",0,1)/_xlfn.XLOOKUP($A10,IS!$A$1:$A$27,IS!C$1:C$27," ",0,1)) -1,"") -> 0.10728895 | C10: =IFERROR((_xlfn.XLOOKUP($A10,IS!$A$1:$A$27,IS!C$1:C$27," ",0,1)/_xlfn.XLOOKUP($A10,IS!$A$1:$A$27,IS!D$1:D$27," ",0,1)) -1,"") -> 0.33236562 | D10: =IFERROR((_xlfn.XLOOKUP($A10,IS!$A$1:$A$27,IS!D$1:D$27," ",0,1)/_xlfn.XLOOKUP($A10,IS!$A$1:$A$27,IS!E$1:E$27," ",0,1)) -1,"") -> 0.11230746 | E10: =IFERROR((_xlfn.XLOOKUP($A10,IS!$A$1:$A$27,IS!E$1:E$27," ",0,1)/_xlfn.XLOOKUP($A10,IS!$A$1:$A$27,IS!F$1:F$27," ",0,1)) -1,"") -> 0.088693386
A11: =IS!A11 -> (b) Purchases of products for sale | B11: =IFERROR((_xlfn.XLOOKUP($A11,IS!$A$1:$A$27,IS!B$1:B$27," ",0,1)/_xlfn.XLOOKUP($A11,IS!$A$1:$A$27,IS!C$1:C$27," ",0,1)) -1,"") -> 0.022207422 | C11: =IFERROR((_xlfn.XLOOKUP($A11,IS!$A$1:$A$27,IS!C$1:C$27," ",0,1)/_xlfn.XLOOKUP($A11,IS!$A$1:$A$27,IS!D$1:D$27," ",0,1)) -1,"") -> 0.30443738 | D11: =IFERROR((_xlfn.XLOOKUP($A11,IS!$A$1:$A$27,IS!D$1:D$27," ",0,1)/_xlfn.XLOOKUP($A11,IS!$A$1:$A$27,IS!E$1:E$27," ",0,1)) -1,"") -> -0.33094353 | E11: =IFERROR((_xlfn.XLOOKUP($A11,IS!$A$1:$A$27,IS!E$1:E$27," ",0,1)/_xlfn.XLOOKUP($A11,IS!$A$1:$A$27,IS!F$1:F$27," ",0,1)) -1,"") -> 0.32360501
A12: =IS!A12 -> (c) Changes in Stock | B12: =IFERROR((_xlfn.XLOOKUP($A12,IS!$A$1:$A$27,IS!B$1:B$27," ",0,1)/_xlfn.XLOOKUP($A12,IS!$A$1:$A$27,IS!C$1:C$27," ",0,1)) -1,"") -> 2.5823929 | C12: =IFERROR((_xlfn.XLOOKUP($A12,IS!$A$1:$A$27,IS!C$1:C$27," ",0,1)/_xlfn.XLOOKUP($A12,IS!$A$1:$A$27,IS!D$1:D$27," ",0,1)) -1,"") -> -2.2001139 | D12: =IFERROR((_xlfn.XLOOKUP($A12,IS!$A$1:$A$27,IS!D$1:D$27," ",0,1)/_xlfn.XLOOKUP($A12,IS!$A$1:$A$27,IS!E$1:E$27," ",0,1)) -1,"") -> 2.7229904 | E12: =IFERROR((_xlfn.XLOOKUP($A12,IS!$A$1:$A$27,IS!E$1:E$27," ",0,1)/_xlfn.XLOOKUP($A12,IS!$A$1:$A$27,IS!F$1:F$27," ",0,1)) -1,"") -> -1.1501079
A13: =IS!A13 -> (d) Employee benefits expense | B13: =IFERROR((_xlfn.XLOOKUP($A13,IS!$A$1:$A$27,IS!B$1:B$27," ",0,1)/_xlfn.XLOOKUP($A13,IS!$A$1:$A$27,IS!C$1:C$27," ",0,1)) -1,"") -> 0.071244744 | C13: =IFERROR((_xlfn.XLOOKUP($A13,IS!$A$1:$A$27,IS!C$1:C$27," ",0,1)/_xlfn.XLOOKUP($A13,IS!$A$1:$A$27,IS!D$1:D$27," ",0,1)) -1,"") -> 0.11665107 | D13: =IFERROR((_xlfn.XLOOKUP($A13,IS!$A$1:$A$27,IS!D$1:D$27," ",0,1)/_xlfn.XLOOKUP($A13,IS!$A$1:$A$27,IS!E$1:E$27," ",0,1)) -1,"") -> -0.096849829 | E13: =IFERROR((_xlfn.XLOOKUP($A13,IS!$A$1:$A$27,IS!E$1:E$27," ",0,1)/_xlfn.XLOOKUP($A13,IS!$A$1:$A$27,IS!F$1:F$27," ",0,1)) -1,"") -> -0.090456651
A14: =IS!A14 -> (e) Finance costs | B14: =IFERROR((_xlfn.XLOOKUP($A14,IS!$A$1:$A$27,IS!B$1:B$27," ",0,1)/_xlfn.XLOOKUP($A14,IS!$A$1:$A$27,IS!C$1:C$27," ",0,1)) -1,"") -> -0.16691982 | C14: =IFERROR((_xlfn.XLOOKUP($A14,IS!$A$1:$A$27,IS!C$1:C$27," ",0,1)/_xlfn.XLOOKUP($A14,IS!$A$1:$A$27,IS!D$1:D$27," ",0,1)) -1,"") -> -0.034980888 | D14: =IFERROR((_xlfn.XLOOKUP($A14,IS!$A$1:$A$27,IS!D$1:D$27," ",0,1)/_xlfn.XLOOKUP($A14,IS!$A$1:$A$27,IS!E$1:E$27," ",0,1)) -1,"") -> -0.072917622 | E14: =IFERROR((_xlfn.XLOOKUP($A14,IS!$A$1:$A$27,IS!E$1:E$27," ",0,1)/_xlfn.XLOOKUP($A14,IS!$A$1:$A$27,IS!F$1:F$27," ",0,1)) -1,"") -> 0.15996452
A15: =IS!A15 -> (f) Foreign exchange loss (net) | B15: =IFERROR((_xlfn.XLOOKUP($A15,IS!$A$1:$A$27,IS!B$1:B$27," ",0,1)/_xlfn.XLOOKUP($A15,IS!$A$1:$A$27,IS!C$1:C$27," ",0,1)) -1,"") -> -0.28252788 | C15: =IFERROR((_xlfn.XLOOKUP($A15,IS!$A$1:$A$27,IS!C$1:C$27," ",0,1)/_xlfn.XLOOKUP($A15,IS!$A$1:$A$27,IS!D$1:D$27," ",0,1)) -1,"") -> 1.0448798 | D15: =IFERROR((_xlfn.XLOOKUP($A15,IS!$A$1:$A$27,IS!D$1:D$27," ",0,1)/_xlfn.XLOOKUP($A15,IS!$A$1:$A$27,IS!E$1:E$27," ",0,1)) -1,"") -> 3.7143349 | E15: =IFERROR((_xlfn.XLOOKUP($A15,IS!$A$1:$A$27,IS!E$1:E$27," ",0,1)/_xlfn.XLOOKUP($A15,IS!$A$1:$A$27,IS!F$1:F$27," ",0,1)) -1,"") -> -0.87857741
... A27: =IS!A27 -> XI. Total comprehensive income/(loss) for the year | B27: =IFERROR((_xlfn.XLOOKUP($A27,IS!$A$1:$A$27,IS!B$1:B$27," ",0,1)/_xlfn.XLOOKUP($A27,IS!$A$1:$A$27,IS!C$1:C$27," ",0,1)) -1,"") -> 2.4012498 | C27: =IFERROR((_xlfn.XLOOKUP($A27,IS!$A$1:$A$27,IS!C$1:C$27," ",0,1)/_xlfn.XLOOKUP($A27,IS!$A$1:$A$27,IS!D$1:D$27," ",0,1)) -1,"") -> -2.9347212 | D27: =IFERROR((_xlfn.XLOOKUP($A27,IS!$A$1:$A$27,IS!D$1:D$27," ",0,1)/_xlfn.XLOOKUP($A27,IS!$A$1:$A$27,IS!E$1:E$27," ",0,1)) -1,"") -> -0.35097954 | E27: =IFERROR((_xlfn.XLOOKUP($A27,IS!$A$1:$A$27,IS!E$1:E$27," ",0,1)/_xlfn.XLOOKUP($A27,IS!$A$1:$A$27,IS!F$1:F$27," ",0,1)) -1,"") -> -0.74538851

Sheet BS_COMP
A1: =BS!A1 -> Balance Sheet of Tata Motors from FY2020 TO FY2024
A2: =BS!A2 -> Particulars | B2: =BS!B2 -> FY2024 | C2: =BS!C2 -> FY2023 | D2: =BS!D2 -> FY2022 | E2: =BS!E2 -> FY2021 | F2: =BS!F2 -> FY2020
A3: =BS!A3 -> I. ASSETS
A4: =BS!A4 -> (1) NON-CURRENT ASSETS | B4: =IFERROR(_xlfn.XLOOKUP($A4,BS!$A$1:$A$36,BS!B$1:B$36,"",0,1)/_xlfn.XLOOKUP($A4,BS!$A$1:$A$36,BS!C$1:C$36,"",0,1)-1,"") -> 0.092947657 | C4: =IFERROR(_xlfn.XLOOKUP($A4,BS!$A$1:$A$36,BS!C$1:C$36,"",0,1)/_xlfn.XLOOKUP($A4,BS!$A$1:$A$36,BS!D$1:D$36,"",0,1)-1,"") -> 0.067877264 | D4: =IFERROR(_xlfn.XLOOKUP($A4,BS!$A$1:$A$36,BS!D$1:D$36,"",0,1)/_xlfn.XLOOKUP($A4,BS!$A$1:$A$36,BS!E$1:E$36,"",0,1)-1,"") -> 0.022294869 | E4: =IFERROR(_xlfn.XLOOKUP($A4,BS!$A$1:$A$36,BS!E$1:E$36,"",0,1)/_xlfn.XLOOKUP($A4,BS!$A$1:$A$36,BS!F$1:F$36,"",0,1)-1,"") -> -0.35896847
A5: =BS!A5 -> Property, plant and equipment (PPE) | B5: =IFERROR(_xlfn.XLOOKUP($A5,BS!$A$1:$A$36,BS!B$1:B$36,"",0,1)/_xlfn.XLOOKUP($A5,BS!$A$1:$A$36,BS!C$1:C$36,"",0,1)-1,"") -> -0.0098845326 | C5: =IFERROR(_xlfn.XLOOKUP($A5,BS!$A$1:$A$36,BS!C$1:C$36,"",0,1)/_xlfn.XLOOKUP($A5,BS!$A$1:$A$36,BS!D$1:D$36,"",0,1)-1,"") -> 0.030952449 | D5: =IFERROR(_xlfn.XLOOKUP($A5,BS!$A$1:$A$36,BS!D$1:D$36,"",0,1)/_xlfn.XLOOKUP($A5,BS!$A$1:$A$36,BS!E$1:E$36,"",0,1)-1,"") -> -0.31103118 | E5: =IFERROR(_xlfn.XLOOKUP($A5,BS!$A$1:$A$36,BS!E$1:E$36,"",0,1)/_xlfn.XLOOKUP($A5,BS!$A$1:$A$36,BS!F$1:F$36,"",0,1)-1,"") -> -0.091551068
A6: =BS!A6 -> Capital work-in-progress (CWIP) | B6: =IFERROR(_xlfn.XLOOKUP($A6,BS!$A$1:$A$36,BS!B$1:B$36,"",0,1)/_xlfn.XLOOKUP($A6,BS!$A$1:$A$36,BS!C$1:C$36,"",0,1)-1,"") -> 0 | C6: =IFERROR(_xlfn.XLOOKUP($A6,BS!$A$1:$A$36,BS!C$1:C$36,"",0,1)/_xlfn.XLOOKUP($A6,BS!$A$1:$A$36,BS!D$1:D$36,"",0,1)-1,"") -> -0.016336016 | D6: =IFERROR(_xlfn.XLOOKUP($A6,BS!$A$1:$A$36,BS!D$1:D$36,"",0,1)/_xlfn.XLOOKUP($A6,BS!$A$1:$A$36,BS!E$1:E$36,"",0,1)-1,"") -> -0.55806858 | E6: =IFERROR(_xlfn.XLOOKUP($A6,BS!$A$1:$A$36,BS!E$1:E$36,"",0,1)/_xlfn.XLOOKUP($A6,BS!$A$1:$A$36,BS!F$1:F$36,"",0,1)-1,"") -> -0.24568359
A7: =BS!A7 -> Right of use assets (ROU) | B7: =IFERROR(_xlfn.XLOOKUP($A7,BS!$A$1:$A$36,BS!B$1:B$36,"",0,1)/_xlfn.XLOOKUP($A7,BS!$A$1:$A$36,BS!C$1:C$36,"",0,1)-1,"") -> -0.017286461 | C7: =IFERROR(_xlfn.XLOOKUP($A7,BS!$A$1:$A$36,BS!C$1:C$36,"",0,1)/_xlfn.XLOOKUP($A7,BS!$A$1:$A$36,BS!D$1:D$36,"",0,1)-1,"") -> 0.035343661 | D7: =IFERROR(_xlfn.XLOOKUP($A7,BS!$A$1:$A$36,BS!D$1:D$36,"",0,1)/_xlfn.XLOOKUP($A7,BS!$A$1:$A$36,BS!E$1:E$36,"",0,1)-1,"") -> -0.66058521 | E7: =IFERROR(_xlfn.XLOOKUP($A7,BS!$A$1:$A$36,BS!E$1:E$36,"",0,1)/_xlfn.XLOOKUP($A7,BS!$A$1:$A$36,BS!F$1:F$36,"",0,1)-1,"") -> 0.46282744
A8: =BS!A8 -> Goodwill | B8: =IFERROR(_xlfn.XLOOKUP($A8,BS!$A$1:$A$36,BS!B$1:B$36,"",0,1)/_xlfn.XLOOKUP($A8,BS!$A$1:$A$36,BS!C$1:C$36,"",0,1)-1,"") -> 0 | C8: =IFERROR(_xlfn.XLOOKUP($A8,BS!$A$1:$A$36,BS!C$1:C$36,"",0,1)/_xlfn.XLOOKUP($A8,BS!$A$1:$A$36,BS!D$1:D$36,"",0,1)-1,"") -> 0 | D8: =IFERROR(_xlfn.XLOOKUP($A8,BS!$A$1:$A$36,BS!D$1:D$36,"",0,1)/_xlfn.XLOOKUP($A8,BS!$A$1:$A$36,BS!E$1:E$36,"",0,1)-1,"") -> 0 | E8: =IFERROR(_xlfn.XLOOKUP($A8,BS!$A$1:$A$36,BS!E$1:E$36,"",0,1)/_xlfn.XLOOKUP($A8,BS!$A$1:$A$36,BS!F$1:F$36,"",0,1)-1,"") -> 0
A9: =BS!A9 -> Other intangible assets | B9: =IFERROR(_xlfn.XLOOKUP($A9,BS!$A$1:$A$36,BS!B$1:B$36,"",0,1)/_xlfn.XLOOKUP($A9,BS!$A$1:$A$36,BS!C$1:C$36,"",0,1)-1,"") -> -0.076390775 | C9: =IFERROR(_xlfn.XLOOKUP($A9,BS!$A$1:$A$36,BS!C$1:C$36,"",0,1)/_xlfn.XLOOKUP($A9,BS!$A$1:$A$36,BS!D$1:D$36,"",0,1)-1,"") -> -0.047321469 | D9: =IFERROR(_xlfn.XLOOKUP($A9,BS!$A$1:$A$36,BS!D$1:D$36,"",0,1)/_xlfn.XLOOKUP($A9,BS!$A$1:$A$36,BS!E$1:E$36,"",0,1)-1,"") -> -0.67354009 | E9: =IFERROR(_xlfn.XLOOKUP($A9,BS!$A$1:$A$36,BS!E$1:E$36,"",0,1)/_xlfn.XLOOKUP($A9,BS!$A$1:$A$36,BS!F$1:F$36,"",0,1)-1,"") -> 0.10557695
A10: =BS!A10 -> Intangible assets under development | B10: =IFERROR(_xlfn.XLOOKUP($A10,BS!$A$1:$A$36,BS!B$1:B$36,"",0,1)/_xlfn.XLOOKUP($A10,BS!$A$1:$A$36,BS!C$1:C$36,"",0,1)-1,"") -> 0 | C10: =IFERROR(_xlfn.XLOOKUP($A10,BS!$A$1:$A$36,BS!C$1:C$36,"",0,1)/_xlfn.XLOOKUP($A10,BS!$A$1:$A$36,BS!D$1:D$36,"",0,1)-1,"") -> -0.422582 | D10: =IFERROR(_xlfn.XLOOKUP($A10,BS!$A$1:$A$36,BS!D$1:D$36,"",0,1)/_xlfn.XLOOKUP($A10,BS!$A$1:$A$36,BS!E$1:E$36,"",0,1)-1,"") -> -0.45018482 | E10: =IFERROR(_xlfn.XLOOKUP($A10,BS!$A$1:$A$36,BS!E$1:E$36,"",0,1)/_xlfn.XLOOKUP($A10,BS!$A$1:$A$36,BS!F$1:F$36,"",0,1)-1,"") -> -0.41436285
A11: =BS!A11 -> Investments in subsidiaries, JVs & associates | B11: =IFERROR(_xlfn.XLOOKUP($A11,BS!$A$1:$A$36,BS!B$1:B$36,"",0,1)/_xlfn.XLOOKUP($A11,BS!$A$1:$A$36,BS!C$1:C$36,"",0,1)-1,"") -> -0.077116039 | C11: =IFERROR(_xlfn.XLOOKUP($A11,BS!$A$1:$A$36,BS!C$1:C$36,"",0,1)/_xlfn.XLOOKUP($A11,BS!$A$1:$A$36,BS!D$1:D$36,"",0,1)-1,"") -> 0.13159468 | D11: =IFERROR(_xlfn.XLOOKUP($A11,BS!$A$1:$A$36,BS!D$1:D$36,"",0,1)/_xlfn.XLOOKUP($A11,BS!$A$1:$A$36,BS!E$1:E$36,"",0,1)-1,"") -> 0.73038116 | E11: =IFERROR(_xlfn.XLOOKUP($A11,BS!$A$1:$A$36,BS!E$1:E$36,"",0,1)/_xlfn.XLOOKUP($A11,BS!$A$1:$A$36,BS!F$1:F$36,"",0,1)-1,"") -> -0.058916672
A12: =BS!A12 -> Financial assets (Investments, Loans, Others) | B12: =IFERROR(_xlfn.XLOOKUP($A12,BS!$A$1:$A$36,BS!B$1:B$36,"",0,1)/_xlfn.XLOOKUP($A12,BS!$A$1:$A$36,BS!C$1:C$36,"",0,1)-1,"") -> -0.084647972 | C12: =IFERROR(_xlfn.XLOOKUP($A12,BS!$A$1:$A$36,BS!C$1:C$36,"",0,1)/_xlfn.XLOOKUP($A12,BS!$A$1:$A$36,BS!D$1:D$36,"",0,1)-1,"") -> -0.069920468 | D12: =IFERROR(_xlfn.XLOOKUP($A12,BS!$A$1:$A$36,BS!D$1:D$36,"",0,1)/_xlfn.XLOOKUP($A12,BS!$A$1:$A$36,BS!E$1:E$36,"",0,1)-1,"") -> -1.8915205 | E12: =IFERROR(_xlfn.XLOOKUP($A12,BS!$A$1:$A$36,BS!E$1:E$36,"",0,1)/_xlfn.XLOOKUP($A12,BS!$A$1:$A$36,BS!F$1:F$36,"",0,1)-1,"") -> -0.23293854
A13: =BS!A13 -> Non-current tax assets (Net) | B13: =IFERROR(_xlfn.XLOOKUP($A13,BS!$A$1:$A$36,BS!B$1:B$36,"",0,1)/_xlfn.XLOOKUP($A13,BS!$A$1:$A$36,BS!C$1:C$36,"",0,1)-1,"") -> -0.082898733 | C13: =IFERROR(_xlfn.XLOOKUP($A13,BS!$A$1:$A$36,BS!C$1:C$36,"",0,1)/_xlfn.XLOOKUP($A13,BS!$A$1:$A$36,BS!D$1:D$36,"",0,1)-1,"") -> 0.033911518 | D13: =IFERROR(_xlfn.XLOOKUP($A13,BS!$A$1:$A$36,BS!D$1:D$36,"",0,1)/_xlfn.XLOOKUP($A13,BS!$A$1:$A$36,BS!E$1:E$36,"",0,1)-1,"") -> 1.4927262 | E13: =IFERROR(_xlfn.XLOOKUP($A13,BS!$A$1:$A$36,BS!E$1:E$36,"",0,1)/_xlfn.XLOOKUP($A13,BS!$A$1:$A$36,BS!F$1:F$36,"",0,1)-1,"") -> 0.017926563
A14: =BS!A14 -> Other non-current assets | B14: =IFERROR(_xlfn.XLOOKUP($A14,BS!$A$1:$A$36,BS!B$1:B$36,"",0,1)/_xlfn.XLOOKUP($A14,BS!$A$1:$A$36,BS!C$1:C$36,"",0,1)-1,"") -> -0.095482903 | C14: =IFERROR(_xlfn.XLOOKUP($A14,BS!$A$1:$A$36,BS!C$1:C$36,"",0,1)/_xlfn.XLOOKUP($A14,BS!$A$1:$A$36,BS!D$1:D$36,"",0,1)-1,"") -> -0.30106582 | D14: =IFERROR(_xlfn.XLOOKUP($A14,BS!$A$1:$A$36,BS!D$1:D$36,"",0,1)/_xlfn.XLOOKUP($A14,BS!$A$1:$A$36,BS!E$1:E$36,"",0,1)-1,"") -> -2.9488157 | E14: =IFERROR(_xlfn.XLOOKUP($A14,BS!$A$1:$A$36,BS!E$1:E$36,"",0,1)/_xlfn.XLOOKUP($A14,BS!$A$1:$A$36,BS!F$1:F$36,"",0,1)-1,"") -> -0.12524833
A15: =BS!A15 -> (2) CURRENT ASSETS | B15: =IFERROR(_xlfn.XLOOKUP($A15,BS!$A$1:$A$36,BS!B$1:B$36,"",0,1)/_xlfn.XLOOKUP($A15,BS!$A$1:$A$36,BS!C$1:C$36,"",0,1)-1,"") -> 0.34946408 | C15: =IFERROR(_xlfn.XLOOKUP($A15,BS!$A$1:$A$36,BS!C$1:C$36,"",0,1)/_xlfn.XLOOKUP($A15,BS!$A$1:$A$36,BS!D$1:D$36,"",0,1)-1,"") -> 0.0028680064 | D15: =IFERROR(_xlfn.XLOOKUP($A15,BS!$A$1:$A$36,BS!D$1:D$36,"",0,1)/_xlfn.XLOOKUP($A15,BS!$A$1:$A$36,BS!E$1:E$36,"",0,1)-1,"") -> 0.058568269 | E15: =IFERROR(_xlfn.XLOOKUP($A15,BS!$A$1:$A$36,BS!E$1:E$36,"",0,1)/_xlfn.XLOOKUP($A15,BS!$A$1:$A$36,BS!F$1:F$36,"",0,1)-1,"") -> 2.2193283
... A20: =BS!A20 -> TOTAL ASSETS (1) + (2) | B20: =IFERROR(_xlfn.XLOOKUP($A20,BS!$A$1:$A$36,BS!B$1:B$36,"",0,1)/_xlfn.XLOOKUP($A20,BS!$A$1:$A$36,BS!C$1:C$36,"",0,1)-1,"") -> 0.20795559 | C20: =IFERROR(_xlfn.XLOOKUP($A20,BS!$A$1:$A$36,BS!C$1:C$36,"",0,1)/_xlfn.XLOOKUP($A20,BS!$A$1:$A$36,BS!D$1:D$36,"",0,1)-1,"") -> 0.037717821 | D20: =IFERROR(_xlfn.XLOOKUP($A20,BS!$A$1:$A$36,BS!D$1:D$36,"",0,1)/_xlfn.XLOOKUP($A20,BS!$A$1:$A$36,BS!E$1:E$36,"",0,1)-1,"") -> 0.038808902 | E20: =IFERROR(_xlfn.XLOOKUP($A20,BS!$A$1:$A$36,BS!E$1:E$36,"",0,1)/_xlfn.XLOOKUP($A20,BS!$A$1:$A$36,BS!F$1:F$36,"",0,1)-1,"") -> 0.0088841294
B21: =IFERROR(_xlfn.XLOOKUP($A21,BS!$A$1:$A$36,BS!B$1:B$36,"",0,1)/_xlfn.XLOOKUP($A21,BS!$A$1:$A$36,BS!C$1:C$36,"",0,1)-1,"") | C21: =IFERROR(_xlfn.XLOOKUP($A21,BS!$A$1:$A$36,BS!C$1:C$36,"",0,1)/_xlfn.XLOOKUP($A21,BS!$A$1:$A$36,BS!D$1:D$36,"",0,1)-1,"") | D21: =IFERROR(_xlfn.XLOOKUP($A21,BS!$A$1:$A$36,BS!D$1:D$36,"",0,1)/_xlfn.XLOOKUP($A21,BS!$A$1:$A$36,BS!E$1:E$36,"",0,1)-1,"") | E21: =IFERROR(_xlfn.XLOOKUP($A21,BS!$A$1:$A$36,BS!E$1:E$36,"",0,1)/_xlfn.XLOOKUP($A21,BS!$A$1:$A$36,BS!F$1:F$36,"",0,1)-1,"")
A22: =BS!A22 -> II. EQUITY AND LIABILITIES | B22: =IFERROR(_xlfn.XLOOKUP($A22,BS!$A$1:$A$36,BS!B$1:B$36,"",0,1)/_xlfn.XLOOKUP($A22,BS!$A$1:$A$36,BS!C$1:C$36,"",0,1)-1,"") | C22: =IFERROR(_xlfn.XLOOKUP($A22,BS!$A$1:$A$36,BS!C$1:C$36,"",0,1)/_xlfn.XLOOKUP($A22,BS!$A$1:$A$36,BS!D$1:D$36,"",0,1)-1,"") | D22: =IFERROR(_xlfn.XLOOKUP($A22,BS!$A$1:$A$36,BS!D$1:D$36,"",0,1)/_xlfn.XLOOKUP($A22,BS!$A$1:$A$36,BS!E$1:E$36,"",0,1)-1,"") | E22: =IFERROR(_xlfn.XLOOKUP($A22,BS!$A$1:$A$36,BS!E$1:E$36,"",0,1)/_xlfn.XLOOKUP($A22,BS!$A$1:$A$36,BS!F$1:F$36,"",0,1)-1,"")
A23: =BS!A23 -> (1) EQUITY | B23: =IFERROR(_xlfn.XLOOKUP($A23,BS!$A$1:$A$36,BS!B$1:B$36,"",0,1)/_xlfn.XLOOKUP($A23,BS!$A$1:$A$36,BS!C$1:C$36,"",0,1)-1,"") -> 0.18774249 | C23: =IFERROR(_xlfn.XLOOKUP($A23,BS!$A$1:$A$36,BS!C$1:C$36,"",0,1)/_xlfn.XLOOKUP($A23,BS!$A$1:$A$36,BS!D$1:D$36,"",0,1)-1,"") -> 0.032299522 | D23: =IFERROR(_xlfn.XLOOKUP($A23,BS!$A$1:$A$36,BS!D$1:D$36,"",0,1)/_xlfn.XLOOKUP($A23,BS!$A$1:$A$36,BS!E$1:E$36,"",0,1)-1,"") -> 0.02255262 | E23: =IFERROR(_xlfn.XLOOKUP($A23,BS!$A$1:$A$36,BS!E$1:E$36,"",0,1)/_xlfn.XLOOKUP($A23,BS!$A$1:$A$36,BS!F$1:F$36,"",0,1)-1,"") -> 0.10704146
A24: =BS!A24 -> Equity share capital | B24: =IFERROR(_xlfn.XLOOKUP($A24,BS!$A$1:$A$36,BS!B$1:B$36,"",0,1)/_xlfn.XLOOKUP($A24,BS!$A$1:$A$36,BS!C$1:C$36,"",0,1)-1,"") -> 0.000613561 | C24: =IFERROR(_xlfn.XLOOKUP($A24,BS!$A$1:$A$36,BS!C$1:C$36,"",0,1)/_xlfn.XLOOKUP($A24,BS!$A$1:$A$36,BS!D$1:D$36,"",0,1)-1,"") -> 0.00018279626 | D24: =IFERROR(_xlfn.XLOOKUP($A24,BS!$A$1:$A$36,BS!D$1:D$36,"",0,1)/_xlfn.XLOOKUP($A24,BS!$A$1:$A$36,BS!E$1:E$36,"",0,1)-1,"") -> 9.1406485e-05 | E24: =IFERROR(_xlfn.XLOOKUP($A24,BS!$A$1:$A$36,BS!E$1:E$36,"",0,1)/_xlfn.XLOOKUP($A24,BS!$A$1:$A$36,BS!F$1:F$36,"",0,1)-1,"") -> 0.064304973
A25: =BS!A25 -> Other equity | B25: =IFERROR(_xlfn.XLOOKUP($A25,BS!$A$1:$A$36,BS!B$1:B$36,"",0,1)/_xlfn.XLOOKUP($A25,BS!$A$1:$A$36,BS!C$1:C$36,"",0,1)-1,"") -> 0.19287705 | C25: =IFERROR(_xlfn.XLOOKUP($A25,BS!$A$1:$A$36,BS!C$1:C$36,"",0,1)/_xlfn.XLOOKUP($A25,BS!$A$1:$A$36,BS!D$1:D$36,"",0,1)-1,"") -> 0.033209858 | D25: =IFERROR(_xlfn.XLOOKUP($A25,BS!$A$1:$A$36,BS!D$1:D$36,"",0,1)/_xlfn.XLOOKUP($A25,BS!$A$1:$A$36,BS!E$1:E$36,"",0,1)-1,"") -> 0.023203988 | E25: =IFERROR(_xlfn.XLOOKUP($A25,BS!$A$1:$A$36,BS!E$1:E$36,"",0,1)/_xlfn.XLOOKUP($A25,BS!$A$1:$A$36,BS!F$1:F$36,"",0,1)-1,"") -> 0.10833207
A26: =BS!A26 -> (2) NON-CURRENT LIABILITIES | B26: =IFERROR(_xlfn.XLOOKUP($A26,BS!$A$1:$A$36,BS!B$1:B$36,"",0,1)/_xlfn.XLOOKUP($A26,BS!$A$1:$A$36,BS!C$1:C$36,"",0,1)-1,"") -> 0.37588831 | C26: =IFERROR(_xlfn.XLOOKUP($A26,BS!$A$1:$A$36,BS!C$1:C$36,"",0,1)/_xlfn.XLOOKUP($A26,BS!$A$1:$A$36,BS!D$1:D$36,"",0,1)-1,"") -> 0.11287482 | D26: =IFERROR(_xlfn.XLOOKUP($A26,BS!$A$1:$A$36,BS!D$1:D$36,"",0,1)/_xlfn.XLOOKUP($A26,BS!$A$1:$A$36,BS!E$1:E$36,"",0,1)-1,"") -> -0.105094 | E26: =IFERROR(_xlfn.XLOOKUP($A26,BS!$A$1:$A$36,BS!E$1:E$36,"",0,1)/_xlfn.XLOOKUP($A26,BS!$A$1:$A$36,BS!F$1:F$36,"",0,1)-1,"") -> -0.20677279
A27: =BS!A27 -> Financial liabilities (Borrowings & Lease) | B27: =IFERROR(_xlfn.XLOOKUP($A27,BS!$A$1:$A$36,BS!B$1:B$36,"",0,1)/_xlfn.XLOOKUP($A27,BS!$A$1:$A$36,BS!C$1:C$36,"",0,1)-1,"") -> 0.51967925 | C27: =IFERROR(_xlfn.XLOOKUP($A27,BS!$A$1:$A$36,BS!C$1:C$36,"",0,1)/_xlfn.XLOOKUP($A27,BS!$A$1:$A$36,BS!D$1:D$36,"",0,1)-1,"") -> 0.16669486 | D27: =IFERROR(_xlfn.XLOOKUP($A27,BS!$A$1:$A$36,BS!D$1:D$36,"",0,1)/_xlfn.XLOOKUP($A27,BS!$A$1:$A$36,BS!E$1:E$36,"",0,1)-1,"") -> -0.151121 | E27: =IFERROR(_xlfn.XLOOKUP($A27,BS!$A$1:$A$36,BS!E$1:E$36,"",0,1)/_xlfn.XLOOKUP($A27,BS!$A$1:$A$36,BS!F$1:F$36,"",0,1)-1,"") -> -0.24481305
A28: =BS!A28 -> Provisions | B28: =IFERROR(_xlfn.XLOOKUP($A28,BS!$A$1:$A$36,BS!B$1:B$36,"",0,1)/_xlfn.XLOOKUP($A28,BS!$A$1:$A$36,BS!C$1:C$36,"",0,1)-1,"") -> -0.012403796 | C28: =IFERROR(_xlfn.XLOOKUP($A28,BS!$A$1:$A$36,BS!C$1:C$36,"",0,1)/_xlfn.XLOOKUP($A28,BS!$A$1:$A$36,BS!D$1:D$36,"",0,1)-1,"") -> -0.014664861 | D28: =IFERROR(_xlfn.XLOOKUP($A28,BS!$A$1:$A$36,BS!D$1:D$36,"",0,1)/_xlfn.XLOOKUP($A28,BS!$A$1:$A$36,BS!E$1:E$36,"",0,1)-1,"") -> 0.018559664 | E28: =IFERROR(_xlfn.XLOOKUP($A28,BS!$A$1:$A$36,BS!E$1:E$36,"",0,1)/_xlfn.XLOOKUP($A28,BS!$A$1:$A$36,BS!F$1:F$36,"",0,1)-1,"") -> -0.083543995
A29: =BS!A29 -> Deferred tax liabilities (Net) | B29: =IFERROR(_xlfn.XLOOKUP($A29,BS!$A$1:$A$36,BS!B$1:B$36,"",0,1)/_xlfn.XLOOKUP($A29,BS!$A$1:$A$36,BS!C$1:C$36,"",0,1)-1,"") -> -5.2622951 | C29: =IFERROR(_xlfn.XLOOKUP($A29,BS!$A$1:$A$36,BS!C$1:C$36,"",0,1)/_xlfn.XLOOKUP($A29,BS!$A$1:$A$36,BS!D$1:D$36,"",0,1)-1,"") -> -0.0054347826 | D29: =IFERROR(_xlfn.XLOOKUP($A29,BS!$A$1:$A$36,BS!D$1:D$36,"",0,1)/_xlfn.XLOOKUP($A29,BS!$A$1:$A$36,BS!E$1:E$36,"",0,1)-1,"") -> -1.0049305 | E29: =IFERROR(_xlfn.XLOOKUP($A29,BS!$A$1:$A$36,BS!E$1:E$36,"",0,1)/_xlfn.XLOOKUP($A29,BS!$A$1:$A$36,BS!F$1:F$36,"",0,1)-1,"") -> -48.119949
A30: =BS!A30 -> Other non-current liabilities | B30: =IFERROR(_xlfn.XLOOKUP($A30,BS!$A$1:$A$36,BS!B$1:B$36,"",0,1)/_xlfn.XLOOKUP($A30,BS!$A$1:$A$36,BS!C$1:C$36,"",0,1)-1,"") -> 0.23628258 | C30: =IFERROR(_xlfn.XLOOKUP($A30,BS!$A$1:$A$36,BS!C$1:C$36,"",0,1)/_xlfn.XLOOKUP($A30,BS!$A$1:$A$36,BS!D$1:D$36,"",0,1)-1,"") -> 0.28628143 | D30: =IFERROR(_xlfn.XLOOKUP($A30,BS!$A$1:$A$36,BS!D$1:D$36,"",0,1)/_xlfn.XLOOKUP($A30,BS!$A$1:$A$36,BS!E$1:E$36,"",0,1)-1,"") -> -0.88995146 | E30: =IFERROR(_xlfn.XLOOKUP($A30,BS!$A$1:$A$36,BS!E$1:E$36,"",0,1)/_xlfn.XLOOKUP($A30,BS!$A$1:$A$36,BS!F$1:F$36,"",0,1)-1,"") -> 18.544592
A31: =BS!A31 -> (3) CURRENT LIABILITIES | B31: =IFERROR(_xlfn.XLOOKUP($A31,BS!$A$1:$A$36,BS!B$1:B$36,"",0,1)/_xlfn.XLOOKUP($A31,BS!$A$1:$A$36,BS!C$1:C$36,"",0,1)-1,"") -> 0.15088824 | C31: =IFERROR(_xlfn.XLOOKUP($A31,BS!$A$1:$A$36,BS!C$1:C$36,"",0,1)/_xlfn.XLOOKUP($A31,BS!$A$1:$A$36,BS!D$1:D$36,"",0,1)-1,"") -> 0.010503103 | D31: =IFERROR(_xlfn.XLOOKUP($A31,BS!$A$1:$A$36,BS!D$1:D$36,"",0,1)/_xlfn.XLOOKUP($A31,BS!$A$1:$A$36,BS!E$1:E$36,"",0,1)-1,"") -> 0.14841004 | E31: =IFERROR(_xlfn.XLOOKUP($A31,BS!$A$1:$A$36,BS!E$1:E$36,"",0,1)/_xlfn.XLOOKUP($A31,BS!$A$1:$A$36,BS!F$1:F$36,"",0,1)-1,"") -> 0.035381873
A32: =BS!A32 -> Financial liabilities (Borrowings, Trade Payables, Others) | B32: =IFERROR(_xlfn.XLOOKUP($A32,BS!$A$1:$A$36,BS!B$1:B$36,"",0,1)/_xlfn.XLOOKUP($A32,BS!$A$1:$A$36,BS!C$1:C$36,"",0,1)-1,"") -> 0.17183701 | C32: =IFERROR(_xlfn.XLOOKUP($A32,BS!$A$1:$A$36,BS!C$1:C$36,"",0,1)/_xlfn.XLOOKUP($A32,BS!$A$1:$A$36,BS!D$1:D$36,"",0,1)-1,"") -> 0.0032025015 | D32: =IFERROR(_xlfn.XLOOKUP($A32,BS!$A$1:$A$36,BS!D$1:D$36,"",0,1)/_xlfn.XLOOKUP($A32,BS!$A$1:$A$36,BS!E$1:E$36,"",0,1)-1,"") -> 0.15755374 | E32: =IFERROR(_xlfn.XLOOKUP($A32,BS!$A$1:$A$36,BS!E$1:E$36,"",0,1)/_xlfn.XLOOKUP($A32,BS!$A$1:$A$36,BS!F$1:F$36,"",0,1)-1,"") -> 0.06369241
A33: =BS!A33 -> Provisions | B33: =IFERROR(_xlfn.XLOOKUP($A33,BS!$A$1:$A$36,BS!B$1:B$36,"",0,1)/_xlfn.XLOOKUP($A33,BS!$A$1:$A$36,BS!C$1:C$36,"",0,1)-1,"") -> -0.012403796 | C33: =IFERROR(_xlfn.XLOOKUP($A33,BS!$A$1:$A$36,BS!C$1:C$36,"",0,1)/_xlfn.XLOOKUP($A33,BS!$A$1:$A$36,BS!D$1:D$36,"",0,1)-1,"") -> -0.014664861 | D33: =IFERROR(_xlfn.XLOOKUP($A33,BS!$A$1:$A$36,BS!D$1:D$36,"",0,1)/_xlfn.XLOOKUP($A33,BS!$A$1:$A$36,BS!E$1:E$36,"",0,1)-1,"") -> 0.018559664 | E33: =IFERROR(_xlfn.XLOOKUP($A33,BS!$A$1:$A$36,BS!E$1:E$36,"",0,1)/_xlfn.XLOOKUP($A33,BS!$A$1:$A$36,BS!F$1:F$36,"",0,1)-1,"") -> -0.083543995
... A36: =BS!A36 -> TOTAL EQUITY AND LIABILITIES (1) + (2) + (3) | B36: =IFERROR(_xlfn.XLOOKUP($A36,BS!$A$1:$A$36,BS!B$1:B$36,"",0,1)/_xlfn.XLOOKUP($A36,BS!$A$1:$A$36,BS!C$1:C$36,"",0,1)-1,"") -> 0.20795559 | C36: =IFERROR(_xlfn.XLOOKUP($A36,BS!$A$1:$A$36,BS!C$1:C$36,"",0,1)/_xlfn.XLOOKUP($A36,BS!$A$1:$A$36,BS!D$1:D$36,"",0,1)-1,"") -> 0.037717821 | D36: =IFERROR(_xlfn.XLOOKUP($A36,BS!$A$1:$A$36,BS!D$1:D$36,"",0,1)/_xlfn.XLOOKUP($A36,BS!$A$1:$A$36,BS!E$1:E$36,"",0,1)-1,"") -> 0.038808902 | E36: =IFERROR(_xlfn.XLOOKUP($A36,BS!$A$1:$A$36,BS!E$1:E$36,"",0,1)/_xlfn.XLOOKUP($A36,BS!$A$1:$A$36,BS!F$1:F$36,"",0,1)-1,"") -> 0.0088841294

Sheet IS_COMM
A1: =IS!A1 -> Income Statement of Tata Motors from FY2020 TO FY2024
A2: =IS!A2 -> Particulars | B2: =IS!B2 -> FY2024 | C2: =IS!C2 -> FY2023 | D2: =IS!D2 -> FY2022 | E2: =IS!E2 -> FY2021 | F2: =IS!F2 -> FY2020
A3: =IS!A3 -> I. Revenue from operations
A4: =IS!A4 -> (a) Revenue | B4: =_xlfn.XLOOKUP($A4,IS!$A$2:$A$28,IS!B$2:B$28," ",0,1)/_xlfn.XLOOKUP($A$6,IS!$A$2:$A$28,IS!B$2:B$28," ",0,1) -> 0.99239923 | C4: =_xlfn.XLOOKUP($A4,IS!$A$2:$A$28,IS!C$2:C$28," ",0,1)/_xlfn.XLOOKUP($A$6,IS!$A$2:$A$28,IS!C$2:C$28," ",0,1) -> 0.99302755 | D4: =_xlfn.XLOOKUP($A4,IS!$A$2:$A$28,IS!D$2:D$28," ",0,1)/_xlfn.XLOOKUP($A$6,IS!$A$2:$A$28,IS!D$2:D$28," ",0,1) -> 0.99190266 | E4: =_xlfn.XLOOKUP($A4,IS!$A$2:$A$28,IS!E$2:E$28," ",0,1)/_xlfn.XLOOKUP($A$6,IS!$A$2:$A$28,IS!E$2:E$28," ",0,1) -> 0.98996247 | F4: =_xlfn.XLOOKUP($A4,IS!$A$2:$A$28,IS!F$2:F$28," ",0,1)/_xlfn.XLOOKUP($A$6,IS!$A$2:$A$28,IS!F$2:F$28," ",0,1) -> 0.98992879
A5: =IS!A5 -> (b) Other operating revenue | B5: =_xlfn.XLOOKUP($A5,IS!$A$2:$A$28,IS!B$2:B$28," ",0,1)/_xlfn.XLOOKUP($A$6,IS!$A$2:$A$28,IS!B$2:B$28," ",0,1) -> 0.007600772 | C5: =_xlfn.XLOOKUP($A5,IS!$A$2:$A$28,IS!C$2:C$28," ",0,1)/_xlfn.XLOOKUP($A$6,IS!$A$2:$A$28,IS!C$2:C$28," ",0,1) -> 0.0069724546 | D5: =_xlfn.XLOOKUP($A5,IS!$A$2:$A$28,IS!D$2:D$28," ",0,1)/_xlfn.XLOOKUP($A$6,IS!$A$2:$A$28,IS!D$2:D$28," ",0,1) -> 0.0080973382 | E5: =_xlfn.XLOOKUP($A5,IS!$A$2:$A$28,IS!E$2:E$28," ",0,1)/_xlfn.XLOOKUP($A$6,IS!$A$2:$A$28,IS!E$2:E$28," ",0,1) -> 0.010037534 | F5: =_xlfn.XLOOKUP($A5,IS!$A$2:$A$28,IS!F$2:F$28," ",0,1)/_xlfn.XLOOKUP($A$6,IS!$A$2:$A$28,IS!F$2:F$28," ",0,1) -> 0.010071214
A6: =IS!A6 -> Total revenue from operations (I) | B6: =_xlfn.XLOOKUP($A6,IS!$A$2:$A$28,IS!B$2:B$28," ",0,1)/_xlfn.XLOOKUP($A$6,IS!$A$2:$A$28,IS!B$2:B$28," ",0,1) -> 1 | C6: =_xlfn.XLOOKUP($A6,IS!$A$2:$A$28,IS!C$2:C$28," ",0,1)/_xlfn.XLOOKUP($A$6,IS!$A$2:$A$28,IS!C$2:C$28," ",0,1) -> 1 | D6: =_xlfn.XLOOKUP($A6,IS!$A$2:$A$28,IS!D$2:D$28," ",0,1)/_xlfn.XLOOKUP($A$6,IS!$A$2:$A$28,IS!D$2:D$28," ",0,1) -> 1 | E6: =_xlfn.XLOOKUP($A6,IS!$A$2:$A$28,IS!E$2:E$28," ",0,1)/_xlfn.XLOOKUP($A$6,IS!$A$2:$A$28,IS!E$2:E$28," ",0,1) -> 1 | F6: =_xlfn.XLOOKUP($A6,IS!$A$2:$A$28,IS!F$2:F$28," ",0,1)/_xlfn.XLOOKUP($A$6,IS!$A$2:$A$28,IS!F$2:F$28," ",0,1) -> 1
A7: =IS!A7 -> II. Other Income | B7: =_xlfn.XLOOKUP($A7,IS!$A$2:$A$28,IS!B$2:B$28," ",0,1)/_xlfn.XLOOKUP($A$6,IS!$A$2:$A$28,IS!B$2:B$28," ",0,1) -> 0.015686653 | C7: =_xlfn.XLOOKUP($A7,IS!$A$2:$A$28,IS!C$2:C$28," ",0,1)/_xlfn.XLOOKUP($A$6,IS!$A$2:$A$28,IS!C$2:C$28," ",0,1) -> 0.012484388 | D7: =_xlfn.XLOOKUP($A7,IS!$A$2:$A$28,IS!D$2:D$28," ",0,1)/_xlfn.XLOOKUP($A$6,IS!$A$2:$A$28,IS!D$2:D$28," ",0,1) -> 0.013962307 | E7: =_xlfn.XLOOKUP($A7,IS!$A$2:$A$28,IS!E$2:E$28," ",0,1)/_xlfn.XLOOKUP($A$6,IS!$A$2:$A$28,IS!E$2:E$28," ",0,1) -> 0.017923318 | F7: =_xlfn.XLOOKUP($A7,IS!$A$2:$A$28,IS!F$2:F$28," ",0,1)/_xlfn.XLOOKUP($A$6,IS!$A$2:$A$28,IS!F$2:F$28," ",0,1) -> 0.031484353
A8: =IS!A8 -> III. Total Income (I+II) | B8: =_xlfn.XLOOKUP($A8,IS!$A$2:$A$28,IS!B$2:B$28," ",0,1)/_xlfn.XLOOKUP($A$6,IS!$A$2:$A$28,IS!B$2:B$28," ",0,1) -> 1.0156867 | C8: =_xlfn.XLOOKUP($A8,IS!$A$2:$A$28,IS!C$2:C$28," ",0,1)/_xlfn.XLOOKUP($A$6,IS!$A$2:$A$28,IS!C$2:C$28," ",0,1) -> 1.0124844 | D8: =_xlfn.XLOOKUP($A8,IS!$A$2:$A$28,IS!D$2:D$28," ",0,1)/_xlfn.XLOOKUP($A$6,IS!$A$2:$A$28,IS!D$2:D$28," ",0,1) -> 1.0139623 | E8: =_xlfn.XLOOKUP($A8,IS!$A$2:$A$28,IS!E$2:E$28," ",0,1)/_xlfn.XLOOKUP($A$6,IS!$A$2:$A$28,IS!E$2:E$28," ",0,1) -> 1.0179233 | F8: =_xlfn.XLOOKUP($A8,IS!$A$2:$A$28,IS!F$2:F$28," ",0,1)/_xlfn.XLOOKUP($A$6,IS!$A$2:$A$28,IS!F$2:F$28," ",0,1) -> 1.0314844
A9: =IS!A9 -> IV. Expenses: | B9: =_xlfn.XLOOKUP($A9,IS!$A$2:$A$28,IS!B$2:B$28," ",0,1)/_xlfn.XLOOKUP($A$6,IS!$A$2:$A$28,IS!B$2:B$28," ",0,1) -> 0 | C9: =_xlfn.XLOOKUP($A9,IS!$A$2:$A$28,IS!C$2:C$28," ",0,1)/_xlfn.XLOOKUP($A$6,IS!$A$2:$A$28,IS!C$2:C$28," ",0,1) -> 0 | D9: =_xlfn.XLOOKUP($A9,IS!$A$2:$A$28,IS!D$2:D$28," ",0,1)/_xlfn.XLOOKUP($A$6,IS!$A$2:$A$28,IS!D$2:D$28," ",0,1) -> 0 | E9: =_xlfn.XLOOKUP($A9,IS!$A$2:$A$28,IS!E$2:E$28," ",0,1)/_xlfn.XLOOKUP($A$6,IS!$A$2:$A$28,IS!E$2:E$28," ",0,1) -> 0 | F9: =_xlfn.XLOOKUP($A9,IS!$A$2:$A$28,IS!F$2:F$28," ",0,1)/_xlfn.XLOOKUP($A$6,IS!$A$2:$A$28,IS!F$2:F$28," ",0,1) -> 0
A10: =IS!A10 -> (a) Cost of materials consumed | B10: =_xlfn.XLOOKUP($A10,IS!$A$2:$A$28,IS!B$2:B$28," ",0,1)/_xlfn.XLOOKUP($A$6,IS!$A$2:$A$28,IS!B$2:B$28," ",0,1) -> 0.63786242 | C10: =_xlfn.XLOOKUP($A10,IS!$A$2:$A$28,IS!C$2:C$28," ",0,1)/_xlfn.XLOOKUP($A$6,IS!$A$2:$A$28,IS!C$2:C$28," ",0,1) -> 0.64216126 | D10: =_xlfn.XLOOKUP($A10,IS!$A$2:$A$28,IS!D$2:D$28," ",0,1)/_xlfn.XLOOKUP($A$6,IS!$A$2:$A$28,IS!D$2:D$28," ",0,1) -> 0.67055951 | E10: =_xlfn.XLOOKUP($A10,IS!$A$2:$A$28,IS!E$2:E$28," ",0,1)/_xlfn.XLOOKUP($A$6,IS!$A$2:$A$28,IS!E$2:E$28," ",0,1) -> 0.60583095 | F10: =_xlfn.XLOOKUP($A10,IS!$A$2:$A$28,IS!F$2:F$28," ",0,1)/_xlfn.XLOOKUP($A$6,IS!$A$2:$A$28,IS!F$2:F$28," ",0,1) -> 0.5957874
A11: =IS!A11 -> (b) Purchases of products for sale | B11: =_xlfn.XLOOKUP($A11,IS!$A$2:$A$28,IS!B$2:B$28," ",0,1)/_xlfn.XLOOKUP($A$6,IS!$A$2:$A$28,IS!B$2:B$28," ",0,1) -> 0.091497247 | C11: =_xlfn.XLOOKUP($A11,IS!$A$2:$A$28,IS!C$2:C$28," ",0,1)/_xlfn.XLOOKUP($A$6,IS!$A$2:$A$28,IS!C$2:C$28," ",0,1) -> 0.099780815 | D11: =_xlfn.XLOOKUP($A11,IS!$A$2:$A$28,IS!D$2:D$28," ",0,1)/_xlfn.XLOOKUP($A$6,IS!$A$2:$A$28,IS!D$2:D$28," ",0,1) -> 0.10642421 | E11: =_xlfn.XLOOKUP($A11,IS!$A$2:$A$28,IS!E$2:E$28," ",0,1)/_xlfn.XLOOKUP($A$6,IS!$A$2:$A$28,IS!E$2:E$28," ",0,1) -> 0.15985148 | F11: =_xlfn.XLOOKUP($A11,IS!$A$2:$A$28,IS!F$2:F$28," ",0,1)/_xlfn.XLOOKUP($A$6,IS!$A$2:$A$28,IS!F$2:F$28," ",0,1) -> 0.12930154
A12: =IS!A12 -> (c) Changes in Stock | B12: =_xlfn.XLOOKUP($A12,IS!$A$2:$A$28,IS!B$2:B$28," ",0,1)/_xlfn.XLOOKUP($A$6,IS!$A$2:$A$28,IS!B$2:B$28," ",0,1) -> 0.023687272 | C12: =_xlfn.XLOOKUP($A12,IS!$A$2:$A$28,IS!C$2:C$28," ",0,1)/_xlfn.XLOOKUP($A$6,IS!$A$2:$A$28,IS!C$2:C$28," ",0,1) -> 0.0073708893 | D12: =_xlfn.XLOOKUP($A12,IS!$A$2:$A$28,IS!D$2:D$28," ",0,1)/_xlfn.XLOOKUP($A$6,IS!$A$2:$A$28,IS!D$2:D$28," ",0,1) -> -0.0085450392 | E12: =_xlfn.XLOOKUP($A12,IS!$A$2:$A$28,IS!E$2:E$28," ",0,1)/_xlfn.XLOOKUP($A$6,IS!$A$2:$A$28,IS!E$2:E$28," ",0,1) -> -0.0023065407 | F12: =_xlfn.XLOOKUP($A12,IS!$A$2:$A$28,IS!F$2:F$28," ",0,1)/_xlfn.XLOOKUP($A$6,IS!$A$2:$A$28,IS!F$2:F$28," ",0,1) -> 0.016451402
A13: =IS!A13 -> (d) Employee benefits expense | B13: =_xlfn.XLOOKUP($A13,IS!$A$2:$A$28,IS!B$2:B$28," ",0,1)/_xlfn.XLOOKUP($A$6,IS!$A$2:$A$28,IS!B$2:B$28," ",0,1) -> 0.058771746 | C13: =_xlfn.XLOOKUP($A13,IS!$A$2:$A$28,IS!C$2:C$28," ",0,1)/_xlfn.XLOOKUP($A$6,IS!$A$2:$A$28,IS!C$2:C$28," ",0,1) -> 0.061158657 | D13: =_xlfn.XLOOKUP($A13,IS!$A$2:$A$28,IS!D$2:D$28," ",0,1)/_xlfn.XLOOKUP($A$6,IS!$A$2:$A$28,IS!D$2:D$28," ",0,1) -> 0.076200372 | E13: =_xlfn.XLOOKUP($A13,IS!$A$2:$A$28,IS!E$2:E$28," ",0,1)/_xlfn.XLOOKUP($A$6,IS!$A$2:$A$28,IS!E$2:E$28," ",0,1) -> 0.084788334 | F13: =_xlfn.XLOOKUP($A13,IS!$A$2:$A$28,IS!F$2:F$28," ",0,1)/_xlfn.XLOOKUP($A$6,IS!$A$2:$A$28,IS!F$2:F$28," ",0,1) -> 0.099806343
A14: =IS!A14 -> (e) Finance costs | B14: =_xlfn.XLOOKUP($A14,IS!$A$2:$A$28,IS!B$2:B$28," ",0,1)/_xlfn.XLOOKUP($A$6,IS!$A$2:$A$28,IS!B$2:B$28," ",0,1) -> 0.023269691 | C14: =_xlfn.XLOOKUP($A14,IS!$A$2:$A$28,IS!C$2:C$28," ",0,1)/_xlfn.XLOOKUP($A$6,IS!$A$2:$A$28,IS!C$2:C$28," ",0,1) -> 0.031137365 | D14: =_xlfn.XLOOKUP($A14,IS!$A$2:$A$28,IS!D$2:D$28," ",0,1)/_xlfn.XLOOKUP($A$6,IS!$A$2:$A$28,IS!D$2:D$28," ",0,1) -> 0.044891342 | E14: =_xlfn.XLOOKUP($A14,IS!$A$2:$A$28,IS!E$2:E$28," ",0,1)/_xlfn.XLOOKUP($A$6,IS!$A$2:$A$28,IS!E$2:E$28," ",0,1) -> 0.048661247 | F14: =_xlfn.XLOOKUP($A14,IS!$A$2:$A$28,IS!F$2:F$28," ",0,1)/_xlfn.XLOOKUP($A$6,IS!$A$2:$A$28,IS!F$2:F$28," ",0,1) -> 0.044914232
A15: =IS!A15 -> (f) Foreign exchange loss (net) | B15: =_xlfn.XLOOKUP($A15,IS!$A$2:$A$28,IS!B$2:B$28," ",0,1)/_xlfn.XLOOKUP($A$6,IS!$A$2:$A$28,IS!B$2:B$28," ",0,1) -> 0.0027382205 | C15: =_xlfn.XLOOKUP($A15,IS!$A$2:$A$28,IS!C$2:C$28," ",0,1)/_xlfn.XLOOKUP($A$6,IS!$A$2:$A$28,IS!C$2:C$28," ",0,1) -> 0.0042544306 | D15: =_xlfn.XLOOKUP($A15,IS!$A$2:$A$28,IS!D$2:D$28," ",0,1)/_xlfn.XLOOKUP($A$6,IS!$A$2:$A$28,IS!D$2:D$28," ",0,1) -> 0.0028946117 | E15: =_xlfn.XLOOKUP($A15,IS!$A$2:$A$28,IS!E$2:E$28," ",0,1)/_xlfn.XLOOKUP($A$6,IS!$A$2:$A$28,IS!E$2:E$28," ",0,1) -> 0.00061703366 | F15: =_xlfn.XLOOKUP($A15,IS!$A$2:$A$28,IS!F$2:F$28," ",0,1)/_xlfn.XLOOKUP($A$6,IS!$A$2:$A$28,IS!F$2:F$28," ",0,1) -> 0.0054407001
... A27: =IS!A27 -> XI. Total comprehensive income/(loss) for the year | B27: =_xlfn.XLOOKUP($A27,IS!$A$2:$A$28,IS!B$2:B$28," ",0,1)/_xlfn.XLOOKUP($A$6,IS!$A$2:$A$28,IS!B$2:B$28," ",0,1) -> 0.11375566 | C27: =_xlfn.XLOOKUP($A27,IS!$A$2:$A$28,IS!C$2:C$28," ",0,1)/_xlfn.XLOOKUP($A$6,IS!$A$2:$A$28,IS!C$2:C$28," ",0,1) -> 0.037283144 | D27: =_xlfn.XLOOKUP($A27,IS!$A$2:$A$28,IS!D$2:D$28," ",0,1)/_xlfn.XLOOKUP($A$6,IS!$A$2:$A$28,IS!D$2:D$28," ",0,1) -> -0.026810862 | E27: =_xlfn.XLOOKUP($A27,IS!$A$2:$A$28,IS!E$2:E$28," ",0,1)/_xlfn.XLOOKUP($A$6,IS!$A$2:$A$28,IS!E$2:E$28," ",0,1) -> -0.041513693 | F27: =_xlfn.XLOOKUP($A27,IS!$A$2:$A$28,IS!F$2:F$28," ",0,1)/_xlfn.XLOOKUP($A$6,IS!$A$2:$A$28,IS!F$2:F$28," ",0,1) -> -0.17456566

Sheet BS_COMM
A1: =BS!A1 -> Balance Sheet of Tata Motors from FY2020 TO FY2024
A2: =BS!A2 -> Particulars | B2: =BS!B2 -> FY2024 | C2: =BS!C2 -> FY2023 | D2: =BS!D2 -> FY2022 | E2: =BS!E2 -> FY2021 | F2: =BS!F2 -> FY2020
A3: =BS!A3 -> I. ASSETS
A4: =BS!A4 -> (1) NON-CURRENT ASSETS | B4: =_xlfn.XLOOKUP($A4,BS!$A$1:$A$36,BS!B$1:B$36,,0,1)/_xlfn.XLOOKUP($A$20,BS!$A$1:$A$36,BS!B$1:B$36,,0,1) -> 0.49913236 | C4: =_xlfn.XLOOKUP($A4,BS!$A$1:$A$36,BS!C$1:C$36,,0,1)/_xlfn.XLOOKUP($A$20,BS!$A$1:$A$36,BS!C$1:C$36,,0,1) -> 0.55165471 | D4: =_xlfn.XLOOKUP($A4,BS!$A$1:$A$36,BS!D$1:D$36,,0,1)/_xlfn.XLOOKUP($A$20,BS!$A$1:$A$36,BS!D$1:D$36,,0,1) -> 0.53607464 | E4: =_xlfn.XLOOKUP($A4,BS!$A$1:$A$36,BS!E$1:E$36,,0,1)/_xlfn.XLOOKUP($A$20,BS!$A$1:$A$36,BS!E$1:E$36,,0,1) -> 0.54473433 | F4: =_xlfn.XLOOKUP($A4,BS!$A$1:$A$36,BS!F$1:F$36,,0,1)/_xlfn.XLOOKUP($A$20,BS!$A$1:$A$36,BS!F$1:F$36,,0,1) -> 0.85732729
A5: =BS!A5 -> Property, plant and equipment (PPE) | B5: =_xlfn.XLOOKUP($A5,BS!$A$1:$A$36,BS!B$1:B$36,,0,1)/_xlfn.XLOOKUP($A$20,BS!$A$1:$A$36,BS!B$1:B$36,,0,1) -> 0.16654151 | C5: =_xlfn.XLOOKUP($A5,BS!$A$1:$A$36,BS!C$1:C$36,,0,1)/_xlfn.XLOOKUP($A$20,BS!$A$1:$A$36,BS!C$1:C$36,,0,1) -> 0.20318312 | D5: =_xlfn.XLOOKUP($A5,BS!$A$1:$A$36,BS!D$1:D$36,,0,1)/_xlfn.XLOOKUP($A$20,BS!$A$1:$A$36,BS!D$1:D$36,,0,1) -> 0.20451646 | E5: =_xlfn.XLOOKUP($A5,BS!$A$1:$A$36,BS!E$1:E$36,,0,1)/_xlfn.XLOOKUP($A$20,BS!$A$1:$A$36,BS!E$1:E$36,,0,1) -> 0.3083645 | F5: =_xlfn.XLOOKUP($A5,BS!$A$1:$A$36,BS!F$1:F$36,,0,1)/_xlfn.XLOOKUP($A$20,BS!$A$1:$A$36,BS!F$1:F$36,,0,1) -> 0.34245628
A6: =BS!A6 -> Capital work-in-progress (CWIP) | B6: =_xlfn.XLOOKUP($A6,BS!$A$1:$A$36,BS!B$1:B$36,,0,1)/_xlfn.XLOOKUP($A$20,BS!$A$1:$A$36,BS!B$1:B$36,,0,1) -> 0.0079518675 | C6: =_xlfn.XLOOKUP($A6,BS!$A$1:$A$36,BS!C$1:C$36,,0,1)/_xlfn.XLOOKUP($A$20,BS!$A$1:$A$36,BS!C$1:C$36,,0,1) -> 0.0096055028 | D6: =_xlfn.XLOOKUP($A6,BS!$A$1:$A$36,BS!D$1:D$36,,0,1)/_xlfn.XLOOKUP($A$20,BS!$A$1:$A$36,BS!D$1:D$36,,0,1) -> 0.01013334 | E6: =_xlfn.XLOOKUP($A6,BS!$A$1:$A$36,BS!E$1:E$36,,0,1)/_xlfn.XLOOKUP($A$20,BS!$A$1:$A$36,BS!E$1:E$36,,0,1) -> 0.023819541 | F6: =_xlfn.XLOOKUP($A6,BS!$A$1:$A$36,BS!F$1:F$36,,0,1)/_xlfn.XLOOKUP($A$20,BS!$A$1:$A$36,BS!F$1:F$36,,0,1) -> 0.031858192
A7: =BS!A7 -> Right of use assets (ROU) | B7: =_xlfn.XLOOKUP($A7,BS!$A$1:$A$36,BS!B$1:B$36,,0,1)/_xlfn.XLOOKUP($A$20,BS!$A$1:$A$36,BS!B$1:B$36,,0,1) -> 0.0046724905 | C7: =_xlfn.XLOOKUP($A7,BS!$A$1:$A$36,BS!C$1:C$36,,0,1)/_xlfn.XLOOKUP($A$20,BS!$A$1:$A$36,BS!C$1:C$36,,0,1) -> 0.0057434449 | D7: =_xlfn.XLOOKUP($A7,BS!$A$1:$A$36,BS!D$1:D$36,,0,1)/_xlfn.XLOOKUP($A$20,BS!$A$1:$A$36,BS!D$1:D$36,,0,1) -> 0.0057566153 | E7: =_xlfn.XLOOKUP($A7,BS!$A$1:$A$36,BS!E$1:E$36,,0,1)/_xlfn.XLOOKUP($A$20,BS!$A$1:$A$36,BS!E$1:E$36,,0,1) -> 0.017618629 | F7: =_xlfn.XLOOKUP($A7,BS!$A$1:$A$36,BS!F$1:F$36,,0,1)/_xlfn.XLOOKUP($A$20,BS!$A$1:$A$36,BS!F$1:F$36,,0,1) -> 0.012151231
A8: =BS!A8 -> Goodwill | B8: =_xlfn.XLOOKUP($A8,BS!$A$1:$A$36,BS!B$1:B$36,,0,1)/_xlfn.XLOOKUP($A$20,BS!$A$1:$A$36,BS!B$1:B$36,,0,1) -> 0.0013688014 | C8: =_xlfn.XLOOKUP($A8,BS!$A$1:$A$36,BS!C$1:C$36,,0,1)/_xlfn.XLOOKUP($A$20,BS!$A$1:$A$36,BS!C$1:C$36,,0,1) -> 0.0016534513 | D8: =_xlfn.XLOOKUP($A8,BS!$A$1:$A$36,BS!D$1:D$36,,0,1)/_xlfn.XLOOKUP($A$20,BS!$A$1:$A$36,BS!D$1:D$36,,0,1) -> 0.0017158159 | E8: =_xlfn.XLOOKUP($A8,BS!$A$1:$A$36,BS!E$1:E$36,,0,1)/_xlfn.XLOOKUP($A$20,BS!$A$1:$A$36,BS!E$1:E$36,,0,1) -> 0.0017824049 | F8: =_xlfn.XLOOKUP($A8,BS!$A$1:$A$36,BS!F$1:F$36,,0,1)/_xlfn.XLOOKUP($A$20,BS!$A$1:$A$36,BS!F$1:F$36,,0,1) -> 0.00179824
A9: =BS!A9 -> Other intangible assets | B9: =_xlfn.XLOOKUP($A9,BS!$A$1:$A$36,BS!B$1:B$36,,0,1)/_xlfn.XLOOKUP($A$20,BS!$A$1:$A$36,BS!B$1:B$36,,0,1) -> 0.024429424 | C9: =_xlfn.XLOOKUP($A9,BS!$A$1:$A$36,BS!C$1:C$36,,0,1)/_xlfn.XLOOKUP($A$20,BS!$A$1:$A$36,BS!C$1:C$36,,0,1) -> 0.031950373 | D9: =_xlfn.XLOOKUP($A9,BS!$A$1:$A$36,BS!D$1:D$36,,0,1)/_xlfn.XLOOKUP($A$20,BS!$A$1:$A$36,BS!D$1:D$36,,0,1) -> 0.034802371 | E9: =_xlfn.XLOOKUP($A9,BS!$A$1:$A$36,BS!E$1:E$36,,0,1)/_xlfn.XLOOKUP($A$20,BS!$A$1:$A$36,BS!E$1:E$36,,0,1) -> 0.11074258 | F9: =_xlfn.XLOOKUP($A9,BS!$A$1:$A$36,BS!F$1:F$36,,0,1)/_xlfn.XLOOKUP($A$20,BS!$A$1:$A$36,BS!F$1:F$36,,0,1) -> 0.10105713
A10: =BS!A10 -> Intangible assets under development | B10: =_xlfn.XLOOKUP($A10,BS!$A$1:$A$36,BS!B$1:B$36,,0,1)/_xlfn.XLOOKUP($A$20,BS!$A$1:$A$36,BS!B$1:B$36,,0,1) -> 0.0070353272 | C10: =_xlfn.XLOOKUP($A10,BS!$A$1:$A$36,BS!C$1:C$36,,0,1)/_xlfn.XLOOKUP($A$20,BS!$A$1:$A$36,BS!C$1:C$36,,0,1) -> 0.0084983628 | D10: =_xlfn.XLOOKUP($A10,BS!$A$1:$A$36,BS!D$1:D$36,,0,1)/_xlfn.XLOOKUP($A$20,BS!$A$1:$A$36,BS!D$1:D$36,,0,1) -> 0.015272996 | E10: =_xlfn.XLOOKUP($A10,BS!$A$1:$A$36,BS!E$1:E$36,,0,1)/_xlfn.XLOOKUP($A$20,BS!$A$1:$A$36,BS!E$1:E$36,,0,1) -> 0.028856467 | F10: =_xlfn.XLOOKUP($A10,BS!$A$1:$A$36,BS!F$1:F$36,,0,1)/_xlfn.XLOOKUP($A$20,BS!$A$1:$A$36,BS!F$1:F$36,,0,1) -> 0.049711381
A11: =BS!A11 -> Investments in subsidiaries, JVs & associates | B11: =_xlfn.XLOOKUP($A11,BS!$A$1:$A$36,BS!B$1:B$36,,0,1)/_xlfn.XLOOKUP($A$20,BS!$A$1:$A$36,BS!B$1:B$36,,0,1) -> 0.35666111 | C11: =_xlfn.XLOOKUP($A11,BS!$A$1:$A$36,BS!C$1:C$36,,0,1)/_xlfn.XLOOKUP($A$20,BS!$A$1:$A$36,BS!C$1:C$36,,0,1) -> 0.46683094 | D11: =_xlfn.XLOOKUP($A11,BS!$A$1:$A$36,BS!D$1:D$36,,0,1)/_xlfn.XLOOKUP($A$20,BS!$A$1:$A$36,BS!D$1:D$36,,0,1) -> 0.42810274 | E11: =_xlfn.XLOOKUP($A11,BS!$A$1:$A$36,BS!E$1:E$36,,0,1)/_xlfn.XLOOKUP($A$20,BS!$A$1:$A$36,BS!E$1:E$36,,0,1) -> 0.25700519 | F11: =_xlfn.XLOOKUP($A11,BS!$A$1:$A$36,BS!F$1:F$36,,0,1)/_xlfn.XLOOKUP($A$20,BS!$A$1:$A$36,BS!F$1:F$36,,0,1) -> 0.27552125
A12: =BS!A12 -> Financial assets (Investments, Loans, Others) | B12: =_xlfn.XLOOKUP($A12,BS!$A$1:$A$36,BS!B$1:B$36,,0,1)/_xlfn.XLOOKUP($A$20,BS!$A$1:$A$36,BS!B$1:B$36,,0,1) -> -0.017729494 | C12: =_xlfn.XLOOKUP($A12,BS!$A$1:$A$36,BS!C$1:C$36,,0,1)/_xlfn.XLOOKUP($A$20,BS!$A$1:$A$36,BS!C$1:C$36,,0,1) -> -0.023396946 | D12: =_xlfn.XLOOKUP($A12,BS!$A$1:$A$36,BS!D$1:D$36,,0,1)/_xlfn.XLOOKUP($A$20,BS!$A$1:$A$36,BS!D$1:D$36,,0,1) -> -0.026104679 | E12: =_xlfn.XLOOKUP($A12,BS!$A$1:$A$36,BS!E$1:E$36,,0,1)/_xlfn.XLOOKUP($A$20,BS!$A$1:$A$36,BS!E$1:E$36,,0,1) -> 0.030417443 | F12: =_xlfn.XLOOKUP($A12,BS!$A$1:$A$36,BS!F$1:F$36,,0,1)/_xlfn.XLOOKUP($A$20,BS!$A$1:$A$36,BS!F$1:F$36,,0,1) -> 0.040006802
A13: =BS!A13 -> Non-current tax assets (Net) | B13: =_xlfn.XLOOKUP($A13,BS!$A$1:$A$36,BS!B$1:B$36,,0,1)/_xlfn.XLOOKUP($A$20,BS!$A$1:$A$36,BS!B$1:B$36,,0,1) -> 0.024194453 | C13: =_xlfn.XLOOKUP($A13,BS!$A$1:$A$36,BS!C$1:C$36,,0,1)/_xlfn.XLOOKUP($A$20,BS!$A$1:$A$36,BS!C$1:C$36,,0,1) -> 0.031867609 | D13: =_xlfn.XLOOKUP($A13,BS!$A$1:$A$36,BS!D$1:D$36,,0,1)/_xlfn.XLOOKUP($A$20,BS!$A$1:$A$36,BS!D$1:D$36,,0,1) -> 0.031984928 | E13: =_xlfn.XLOOKUP($A13,BS!$A$1:$A$36,BS!E$1:E$36,,0,1)/_xlfn.XLOOKUP($A$20,BS!$A$1:$A$36,BS!E$1:E$36,,0,1) -> 0.013329273 | F13: =_xlfn.XLOOKUP($A13,BS!$A$1:$A$36,BS!F$1:F$36,,0,1)/_xlfn.XLOOKUP($A$20,BS!$A$1:$A$36,BS!F$1:F$36,,0,1) -> 0.013210866
A14: =BS!A14 -> Other non-current assets | B14: =_xlfn.XLOOKUP($A14,BS!$A$1:$A$36,BS!B$1:B$36,,0,1)/_xlfn.XLOOKUP($A$20,BS!$A$1:$A$36,BS!B$1:B$36,,0,1) -> -0.017985186 | C14: =_xlfn.XLOOKUP($A14,BS!$A$1:$A$36,BS!C$1:C$36,,0,1)/_xlfn.XLOOKUP($A$20,BS!$A$1:$A$36,BS!C$1:C$36,,0,1) -> -0.024018679 | D14: =_xlfn.XLOOKUP($A14,BS!$A$1:$A$36,BS!D$1:D$36,,0,1)/_xlfn.XLOOKUP($A$20,BS!$A$1:$A$36,BS!D$1:D$36,,0,1) -> -0.035660885 | E14: =_xlfn.XLOOKUP($A14,BS!$A$1:$A$36,BS!E$1:E$36,,0,1)/_xlfn.XLOOKUP($A$20,BS!$A$1:$A$36,BS!E$1:E$36,,0,1) -> 0.019008901 | F14: =_xlfn.XLOOKUP($A14,BS!$A$1:$A$36,BS!F$1:F$36,,0,1)/_xlfn.XLOOKUP($A$20,BS!$A$1:$A$36,BS!F$1:F$36,,0,1) -> 0.021923683
